INFO:     Will watch for changes in these directories: ['/home/user/dev/gd_advanced_tools']
INFO:     Uvicorn running on http://127.0.0.1:8000 (Press CTRL+C to quit)
INFO:     Started reloader process [1238474] using StatReload
INFO:     Started server process [1238477]
INFO:     Waiting for application startup.
Error in VaultConfigSettingsSource: Vault error: HTTPConnectionPool(host='127.0.0.1', port=8200): Max retries exceeded with url: /v1/auth/token/lookup-self (Caused by NewConnectionError('<urllib3.connection.HTTPConnection object at 0x76f0fd506bd0>: Failed to establish a new connection: [Errno 111] Connection refused'))
Error in VaultConfigSettingsSource: Vault error: HTTPConnectionPool(host='127.0.0.1', port=8200): Max retries exceeded with url: /v1/auth/token/lookup-self (Caused by NewConnectionError('<urllib3.connection.HTTPConnection object at 0x76f0fd49c9b0>: Failed to establish a new connection: [Errno 111] Connection refused'))
Error in VaultConfigSettingsSource: Vault error: HTTPConnectionPool(host='127.0.0.1', port=8200): Max retries exceeded with url: /v1/auth/token/lookup-self (Caused by NewConnectionError('<urllib3.connection.HTTPConnection object at 0x76f0fd4ad700>: Failed to establish a new connection: [Errno 111] Connection refused'))
Error in VaultConfigSettingsSource: Vault error: HTTPConnectionPool(host='127.0.0.1', port=8200): Max retries exceeded with url: /v1/auth/token/lookup-self (Caused by NewConnectionError('<urllib3.connection.HTTPConnection object at 0x76f0fd49d610>: Failed to establish a new connection: [Errno 111] Connection refused'))
Error in VaultConfigSettingsSource: Vault error: HTTPConnectionPool(host='127.0.0.1', port=8200): Max retries exceeded with url: /v1/auth/token/lookup-self (Caused by NewConnectionError('<urllib3.connection.HTTPConnection object at 0x76f0fd4a0f50>: Failed to establish a new connection: [Errno 111] Connection refused'))
Error in VaultConfigSettingsSource: Vault error: HTTPConnectionPool(host='127.0.0.1', port=8200): Max retries exceeded with url: /v1/auth/token/lookup-self (Caused by NewConnectionError('<urllib3.connection.HTTPConnection object at 0x76f0fd4ade50>: Failed to establish a new connection: [Errno 111] Connection refused'))
Error in VaultConfigSettingsSource: Vault error: HTTPConnectionPool(host='127.0.0.1', port=8200): Max retries exceeded with url: /v1/auth/token/lookup-self (Caused by NewConnectionError('<urllib3.connection.HTTPConnection object at 0x76f0fd2910d0>: Failed to establish a new connection: [Errno 111] Connection refused'))
Error in VaultConfigSettingsSource: Vault error: HTTPConnectionPool(host='127.0.0.1', port=8200): Max retries exceeded with url: /v1/auth/token/lookup-self (Caused by NewConnectionError('<urllib3.connection.HTTPConnection object at 0x76f0fd49eb40>: Failed to establish a new connection: [Errno 111] Connection refused'))
Error in VaultConfigSettingsSource: Vault error: HTTPConnectionPool(host='127.0.0.1', port=8200): Max retries exceeded with url: /v1/auth/token/lookup-self (Caused by NewConnectionError('<urllib3.connection.HTTPConnection object at 0x76f0fd4af1a0>: Failed to establish a new connection: [Errno 111] Connection refused'))
Error in VaultConfigSettingsSource: Vault error: HTTPConnectionPool(host='127.0.0.1', port=8200): Max retries exceeded with url: /v1/auth/token/lookup-self (Caused by NewConnectionError('<urllib3.connection.HTTPConnection object at 0x76f0fd4a24e0>: Failed to establish a new connection: [Errno 111] Connection refused'))
Error in VaultConfigSettingsSource: Vault error: HTTPConnectionPool(host='127.0.0.1', port=8200): Max retries exceeded with url: /v1/auth/token/lookup-self (Caused by NewConnectionError('<urllib3.connection.HTTPConnection object at 0x76f0fd49f350>: Failed to establish a new connection: [Errno 111] Connection refused'))
Error in VaultConfigSettingsSource: Vault error: HTTPConnectionPool(host='127.0.0.1', port=8200): Max retries exceeded with url: /v1/auth/token/lookup-self (Caused by NewConnectionError('<urllib3.connection.HTTPConnection object at 0x76f0fd4af140>: Failed to establish a new connection: [Errno 111] Connection refused'))
Error in VaultConfigSettingsSource: Vault error: HTTPConnectionPool(host='127.0.0.1', port=8200): Max retries exceeded with url: /v1/auth/token/lookup-self (Caused by NewConnectionError('<urllib3.connection.HTTPConnection object at 0x76f0fd4a23c0>: Failed to establish a new connection: [Errno 111] Connection refused'))
Error in VaultConfigSettingsSource: Vault error: HTTPConnectionPool(host='127.0.0.1', port=8200): Max retries exceeded with url: /v1/auth/token/lookup-self (Caused by NewConnectionError('<urllib3.connection.HTTPConnection object at 0x76f0fd4a0f50>: Failed to establish a new connection: [Errno 111] Connection refused'))
Error in VaultConfigSettingsSource: Vault error: HTTPConnectionPool(host='127.0.0.1', port=8200): Max retries exceeded with url: /v1/auth/token/lookup-self (Caused by NewConnectionError('<urllib3.connection.HTTPConnection object at 0x76f0fd4a3ef0>: Failed to establish a new connection: [Errno 111] Connection refused'))
Error in VaultConfigSettingsSource: Vault error: HTTPConnectionPool(host='127.0.0.1', port=8200): Max retries exceeded with url: /v1/auth/token/lookup-self (Caused by NewConnectionError('<urllib3.connection.HTTPConnection object at 0x76f0fd4a29f0>: Failed to establish a new connection: [Errno 111] Connection refused'))
2025-02-26 14:08:04,381 INFO sqlalchemy.engine.Engine select pg_catalog.version()
2025-02-26 14:08:04,382 INFO sqlalchemy.engine.Engine [raw sql] ()
2025-02-26 14:08:04,383 INFO sqlalchemy.engine.Engine select current_schema()
2025-02-26 14:08:04,383 INFO sqlalchemy.engine.Engine [raw sql] ()
2025-02-26 14:08:04,383 INFO sqlalchemy.engine.Engine show standard_conforming_strings
2025-02-26 14:08:04,384 INFO sqlalchemy.engine.Engine [raw sql] ()
2025-02-26 14:08:04,756 INFO sqlalchemy.engine.Engine select pg_catalog.version()
2025-02-26 14:08:04,756 INFO sqlalchemy.engine.Engine [raw sql] {}
2025-02-26 14:08:04,756 INFO sqlalchemy.engine.Engine select current_schema()
2025-02-26 14:08:04,756 INFO sqlalchemy.engine.Engine [raw sql] {}
2025-02-26 14:08:04,757 INFO sqlalchemy.engine.Engine show standard_conforming_strings
2025-02-26 14:08:04,757 INFO sqlalchemy.engine.Engine [raw sql] {}
2025-02-26 14:08:04,757 INFO sqlalchemy.engine.Engine BEGIN (implicit)
2025-02-26 14:08:04,760 INFO sqlalchemy.engine.Engine SELECT pg_catalog.pg_class.relname 
FROM pg_catalog.pg_class JOIN pg_catalog.pg_namespace ON pg_catalog.pg_namespace.oid = pg_catalog.pg_class.relnamespace 
WHERE pg_catalog.pg_class.relname = %(table_name)s AND pg_catalog.pg_class.relkind = ANY (ARRAY[%(param_1)s, %(param_2)s, %(param_3)s, %(param_4)s, %(param_5)s]) AND pg_catalog.pg_table_is_visible(pg_catalog.pg_class.oid) AND pg_catalog.pg_namespace.nspname != %(nspname_1)s
2025-02-26 14:08:04,761 INFO sqlalchemy.engine.Engine [generated in 0.00040s] {'table_name': 'apscheduler_jobs', 'param_1': 'r', 'param_2': 'p', 'param_3': 'f', 'param_4': 'v', 'param_5': 'm', 'nspname_1': 'pg_catalog'}
2025-02-26 14:08:04,762 INFO sqlalchemy.engine.Engine COMMIT
2025-02-26 14:08:04,763 INFO sqlalchemy.engine.Engine BEGIN (implicit)
2025-02-26 14:08:04,764 INFO sqlalchemy.engine.Engine INSERT INTO apscheduler_jobs (id, next_run_time, job_state) VALUES (%(id)s, %(next_run_time)s, %(job_state)s)
2025-02-26 14:08:04,764 INFO sqlalchemy.engine.Engine [generated in 0.00032s] {'id': 'check_all_services_job', 'next_run_time': 1740571683.626877, 'job_state': <psycopg2.extensions.Binary object at 0x76f0e52046f0>}
2025-02-26 14:08:04,766 INFO sqlalchemy.engine.Engine ROLLBACK
2025-02-26 14:08:04,766 INFO sqlalchemy.engine.Engine BEGIN (implicit)
2025-02-26 14:08:04,767 INFO sqlalchemy.engine.Engine UPDATE apscheduler_jobs SET next_run_time=%(next_run_time)s, job_state=%(job_state)s WHERE apscheduler_jobs.id = %(id_1)s
2025-02-26 14:08:04,767 INFO sqlalchemy.engine.Engine [generated in 0.00042s] {'next_run_time': 1740571683.626877, 'job_state': <psycopg2.extensions.Binary object at 0x76f0e5204e40>, 'id_1': 'check_all_services_job'}
2025-02-26 14:08:04,769 INFO sqlalchemy.engine.Engine COMMIT
2025-02-26 14:08:04,790 INFO sqlalchemy.engine.Engine BEGIN (implicit)
2025-02-26 14:08:04,791 INFO sqlalchemy.engine.Engine SELECT apscheduler_jobs.id, apscheduler_jobs.job_state 
FROM apscheduler_jobs 
WHERE apscheduler_jobs.next_run_time <= %(next_run_time_1)s ORDER BY apscheduler_jobs.next_run_time
2025-02-26 14:08:04,791 INFO sqlalchemy.engine.Engine [generated in 0.00017s] {'next_run_time_1': 1740568084.790422}
2025-02-26 14:08:04,792 INFO sqlalchemy.engine.Engine COMMIT
2025-02-26 14:08:04,792 INFO sqlalchemy.engine.Engine BEGIN (implicit)
2025-02-26 14:08:04,793 INFO sqlalchemy.engine.Engine SELECT apscheduler_jobs.next_run_time 
FROM apscheduler_jobs 
WHERE apscheduler_jobs.next_run_time IS NOT NULL ORDER BY apscheduler_jobs.next_run_time 
 LIMIT %(param_1)s
2025-02-26 14:08:04,793 INFO sqlalchemy.engine.Engine [generated in 0.00020s] {'param_1': 1}
2025-02-26 14:08:04,794 INFO sqlalchemy.engine.Engine COMMIT
INFO:     Application startup complete.
WARNING:  StatReload detected changes in 'app/api/v1/endpoints/tech.py'. Reloading...
INFO:     Shutting down
INFO:     Waiting for application shutdown.
INFO:     Application shutdown complete.
INFO:     Finished server process [1238477]
INFO:     Started server process [1239079]
INFO:     Waiting for application startup.
Error in VaultConfigSettingsSource: Vault error: HTTPConnectionPool(host='127.0.0.1', port=8200): Max retries exceeded with url: /v1/auth/token/lookup-self (Caused by NewConnectionError('<urllib3.connection.HTTPConnection object at 0x75c7f47f8320>: Failed to establish a new connection: [Errno 111] Connection refused'))
Error in VaultConfigSettingsSource: Vault error: HTTPConnectionPool(host='127.0.0.1', port=8200): Max retries exceeded with url: /v1/auth/token/lookup-self (Caused by NewConnectionError('<urllib3.connection.HTTPConnection object at 0x75c7f48748f0>: Failed to establish a new connection: [Errno 111] Connection refused'))
Error in VaultConfigSettingsSource: Vault error: HTTPConnectionPool(host='127.0.0.1', port=8200): Max retries exceeded with url: /v1/auth/token/lookup-self (Caused by NewConnectionError('<urllib3.connection.HTTPConnection object at 0x75c7f487dc70>: Failed to establish a new connection: [Errno 111] Connection refused'))
Error in VaultConfigSettingsSource: Vault error: HTTPConnectionPool(host='127.0.0.1', port=8200): Max retries exceeded with url: /v1/auth/token/lookup-self (Caused by NewConnectionError('<urllib3.connection.HTTPConnection object at 0x75c7f4875880>: Failed to establish a new connection: [Errno 111] Connection refused'))
Error in VaultConfigSettingsSource: Vault error: HTTPConnectionPool(host='127.0.0.1', port=8200): Max retries exceeded with url: /v1/auth/token/lookup-self (Caused by NewConnectionError('<urllib3.connection.HTTPConnection object at 0x75c7f48952e0>: Failed to establish a new connection: [Errno 111] Connection refused'))
Error in VaultConfigSettingsSource: Vault error: HTTPConnectionPool(host='127.0.0.1', port=8200): Max retries exceeded with url: /v1/auth/token/lookup-self (Caused by NewConnectionError('<urllib3.connection.HTTPConnection object at 0x75c7f487e000>: Failed to establish a new connection: [Errno 111] Connection refused'))
Error in VaultConfigSettingsSource: Vault error: HTTPConnectionPool(host='127.0.0.1', port=8200): Max retries exceeded with url: /v1/auth/token/lookup-self (Caused by NewConnectionError('<urllib3.connection.HTTPConnection object at 0x75c7f4664a10>: Failed to establish a new connection: [Errno 111] Connection refused'))
Error in VaultConfigSettingsSource: Vault error: HTTPConnectionPool(host='127.0.0.1', port=8200): Max retries exceeded with url: /v1/auth/token/lookup-self (Caused by NewConnectionError('<urllib3.connection.HTTPConnection object at 0x75c7f4876720>: Failed to establish a new connection: [Errno 111] Connection refused'))
Error in VaultConfigSettingsSource: Vault error: HTTPConnectionPool(host='127.0.0.1', port=8200): Max retries exceeded with url: /v1/auth/token/lookup-self (Caused by NewConnectionError('<urllib3.connection.HTTPConnection object at 0x75c7f487e030>: Failed to establish a new connection: [Errno 111] Connection refused'))
Error in VaultConfigSettingsSource: Vault error: HTTPConnectionPool(host='127.0.0.1', port=8200): Max retries exceeded with url: /v1/auth/token/lookup-self (Caused by NewConnectionError('<urllib3.connection.HTTPConnection object at 0x75c7f4895d60>: Failed to establish a new connection: [Errno 111] Connection refused'))
Error in VaultConfigSettingsSource: Vault error: HTTPConnectionPool(host='127.0.0.1', port=8200): Max retries exceeded with url: /v1/auth/token/lookup-self (Caused by NewConnectionError('<urllib3.connection.HTTPConnection object at 0x75c7f4875640>: Failed to establish a new connection: [Errno 111] Connection refused'))
Error in VaultConfigSettingsSource: Vault error: HTTPConnectionPool(host='127.0.0.1', port=8200): Max retries exceeded with url: /v1/auth/token/lookup-self (Caused by NewConnectionError('<urllib3.connection.HTTPConnection object at 0x75c7f487d940>: Failed to establish a new connection: [Errno 111] Connection refused'))
Error in VaultConfigSettingsSource: Vault error: HTTPConnectionPool(host='127.0.0.1', port=8200): Max retries exceeded with url: /v1/auth/token/lookup-self (Caused by NewConnectionError('<urllib3.connection.HTTPConnection object at 0x75c7f4897f80>: Failed to establish a new connection: [Errno 111] Connection refused'))
Error in VaultConfigSettingsSource: Vault error: HTTPConnectionPool(host='127.0.0.1', port=8200): Max retries exceeded with url: /v1/auth/token/lookup-self (Caused by NewConnectionError('<urllib3.connection.HTTPConnection object at 0x75c7f48955b0>: Failed to establish a new connection: [Errno 111] Connection refused'))
Error in VaultConfigSettingsSource: Vault error: HTTPConnectionPool(host='127.0.0.1', port=8200): Max retries exceeded with url: /v1/auth/token/lookup-self (Caused by NewConnectionError('<urllib3.connection.HTTPConnection object at 0x75c7f4894c50>: Failed to establish a new connection: [Errno 111] Connection refused'))
Error in VaultConfigSettingsSource: Vault error: HTTPConnectionPool(host='127.0.0.1', port=8200): Max retries exceeded with url: /v1/auth/token/lookup-self (Caused by NewConnectionError('<urllib3.connection.HTTPConnection object at 0x75c7f487cef0>: Failed to establish a new connection: [Errno 111] Connection refused'))
2025-02-26 14:09:06,447 INFO sqlalchemy.engine.Engine select pg_catalog.version()
2025-02-26 14:09:06,447 INFO sqlalchemy.engine.Engine [raw sql] ()
2025-02-26 14:09:06,449 INFO sqlalchemy.engine.Engine select current_schema()
2025-02-26 14:09:06,449 INFO sqlalchemy.engine.Engine [raw sql] ()
2025-02-26 14:09:06,450 INFO sqlalchemy.engine.Engine show standard_conforming_strings
2025-02-26 14:09:06,450 INFO sqlalchemy.engine.Engine [raw sql] ()
2025-02-26 14:09:06,808 INFO sqlalchemy.engine.Engine select pg_catalog.version()
2025-02-26 14:09:06,808 INFO sqlalchemy.engine.Engine [raw sql] {}
2025-02-26 14:09:06,808 INFO sqlalchemy.engine.Engine select current_schema()
2025-02-26 14:09:06,809 INFO sqlalchemy.engine.Engine [raw sql] {}
2025-02-26 14:09:06,809 INFO sqlalchemy.engine.Engine show standard_conforming_strings
2025-02-26 14:09:06,809 INFO sqlalchemy.engine.Engine [raw sql] {}
2025-02-26 14:09:06,809 INFO sqlalchemy.engine.Engine BEGIN (implicit)
2025-02-26 14:09:06,820 INFO sqlalchemy.engine.Engine SELECT pg_catalog.pg_class.relname 
FROM pg_catalog.pg_class JOIN pg_catalog.pg_namespace ON pg_catalog.pg_namespace.oid = pg_catalog.pg_class.relnamespace 
WHERE pg_catalog.pg_class.relname = %(table_name)s AND pg_catalog.pg_class.relkind = ANY (ARRAY[%(param_1)s, %(param_2)s, %(param_3)s, %(param_4)s, %(param_5)s]) AND pg_catalog.pg_table_is_visible(pg_catalog.pg_class.oid) AND pg_catalog.pg_namespace.nspname != %(nspname_1)s
2025-02-26 14:09:06,820 INFO sqlalchemy.engine.Engine [generated in 0.00059s] {'table_name': 'apscheduler_jobs', 'param_1': 'r', 'param_2': 'p', 'param_3': 'f', 'param_4': 'v', 'param_5': 'm', 'nspname_1': 'pg_catalog'}
2025-02-26 14:09:06,823 INFO sqlalchemy.engine.Engine COMMIT
2025-02-26 14:09:06,825 INFO sqlalchemy.engine.Engine BEGIN (implicit)
2025-02-26 14:09:06,826 INFO sqlalchemy.engine.Engine INSERT INTO apscheduler_jobs (id, next_run_time, job_state) VALUES (%(id)s, %(next_run_time)s, %(job_state)s)
2025-02-26 14:09:06,826 INFO sqlalchemy.engine.Engine [generated in 0.00043s] {'id': 'check_all_services_job', 'next_run_time': 1740571745.664968, 'job_state': <psycopg2.extensions.Binary object at 0x75c7dc6a0840>}
2025-02-26 14:09:06,829 INFO sqlalchemy.engine.Engine ROLLBACK
2025-02-26 14:09:06,830 INFO sqlalchemy.engine.Engine BEGIN (implicit)
2025-02-26 14:09:06,831 INFO sqlalchemy.engine.Engine UPDATE apscheduler_jobs SET next_run_time=%(next_run_time)s, job_state=%(job_state)s WHERE apscheduler_jobs.id = %(id_1)s
2025-02-26 14:09:06,831 INFO sqlalchemy.engine.Engine [generated in 0.00034s] {'next_run_time': 1740571745.664968, 'job_state': <psycopg2.extensions.Binary object at 0x75c7dc6a1110>, 'id_1': 'check_all_services_job'}
2025-02-26 14:09:06,832 INFO sqlalchemy.engine.Engine COMMIT
2025-02-26 14:09:06,858 INFO sqlalchemy.engine.Engine BEGIN (implicit)
2025-02-26 14:09:06,859 INFO sqlalchemy.engine.Engine SELECT apscheduler_jobs.id, apscheduler_jobs.job_state 
FROM apscheduler_jobs 
WHERE apscheduler_jobs.next_run_time <= %(next_run_time_1)s ORDER BY apscheduler_jobs.next_run_time
2025-02-26 14:09:06,859 INFO sqlalchemy.engine.Engine [generated in 0.00025s] {'next_run_time_1': 1740568146.858359}
2025-02-26 14:09:06,861 INFO sqlalchemy.engine.Engine COMMIT
2025-02-26 14:09:06,863 INFO sqlalchemy.engine.Engine BEGIN (implicit)
2025-02-26 14:09:06,864 INFO sqlalchemy.engine.Engine SELECT apscheduler_jobs.next_run_time 
FROM apscheduler_jobs 
WHERE apscheduler_jobs.next_run_time IS NOT NULL ORDER BY apscheduler_jobs.next_run_time 
 LIMIT %(param_1)s
2025-02-26 14:09:06,864 INFO sqlalchemy.engine.Engine [generated in 0.00032s] {'param_1': 1}
2025-02-26 14:09:06,865 INFO sqlalchemy.engine.Engine COMMIT
INFO:     Application startup complete.
WARNING:  StatReload detected changes in 'app/background_tasks/workflows.py'. Reloading...
INFO:     Shutting down
INFO:     Waiting for application shutdown.
INFO:     Application shutdown complete.
INFO:     Finished server process [1239079]
INFO:     Started server process [1239760]
INFO:     Waiting for application startup.
Error in VaultConfigSettingsSource: Vault error: HTTPConnectionPool(host='127.0.0.1', port=8200): Max retries exceeded with url: /v1/auth/token/lookup-self (Caused by NewConnectionError('<urllib3.connection.HTTPConnection object at 0x7d2fa75210d0>: Failed to establish a new connection: [Errno 111] Connection refused'))
Error in VaultConfigSettingsSource: Vault error: HTTPConnectionPool(host='127.0.0.1', port=8200): Max retries exceeded with url: /v1/auth/token/lookup-self (Caused by NewConnectionError('<urllib3.connection.HTTPConnection object at 0x7d2fa75d8b00>: Failed to establish a new connection: [Errno 111] Connection refused'))
Error in VaultConfigSettingsSource: Vault error: HTTPConnectionPool(host='127.0.0.1', port=8200): Max retries exceeded with url: /v1/auth/token/lookup-self (Caused by NewConnectionError('<urllib3.connection.HTTPConnection object at 0x7d2fa75e5070>: Failed to establish a new connection: [Errno 111] Connection refused'))
Error in VaultConfigSettingsSource: Vault error: HTTPConnectionPool(host='127.0.0.1', port=8200): Max retries exceeded with url: /v1/auth/token/lookup-self (Caused by NewConnectionError('<urllib3.connection.HTTPConnection object at 0x7d2fa75d9c10>: Failed to establish a new connection: [Errno 111] Connection refused'))
Error in VaultConfigSettingsSource: Vault error: HTTPConnectionPool(host='127.0.0.1', port=8200): Max retries exceeded with url: /v1/auth/token/lookup-self (Caused by NewConnectionError('<urllib3.connection.HTTPConnection object at 0x7d2fa75fd460>: Failed to establish a new connection: [Errno 111] Connection refused'))
Error in VaultConfigSettingsSource: Vault error: HTTPConnectionPool(host='127.0.0.1', port=8200): Max retries exceeded with url: /v1/auth/token/lookup-self (Caused by NewConnectionError('<urllib3.connection.HTTPConnection object at 0x7d2fa75e5dc0>: Failed to establish a new connection: [Errno 111] Connection refused'))
Error in VaultConfigSettingsSource: Vault error: HTTPConnectionPool(host='127.0.0.1', port=8200): Max retries exceeded with url: /v1/auth/token/lookup-self (Caused by NewConnectionError('<urllib3.connection.HTTPConnection object at 0x7d2fa73ccdd0>: Failed to establish a new connection: [Errno 111] Connection refused'))
Error in VaultConfigSettingsSource: Vault error: HTTPConnectionPool(host='127.0.0.1', port=8200): Max retries exceeded with url: /v1/auth/token/lookup-self (Caused by NewConnectionError('<urllib3.connection.HTTPConnection object at 0x7d2fa75db860>: Failed to establish a new connection: [Errno 111] Connection refused'))
Error in VaultConfigSettingsSource: Vault error: HTTPConnectionPool(host='127.0.0.1', port=8200): Max retries exceeded with url: /v1/auth/token/lookup-self (Caused by NewConnectionError('<urllib3.connection.HTTPConnection object at 0x7d2fa75e7710>: Failed to establish a new connection: [Errno 111] Connection refused'))
Error in VaultConfigSettingsSource: Vault error: HTTPConnectionPool(host='127.0.0.1', port=8200): Max retries exceeded with url: /v1/auth/token/lookup-self (Caused by NewConnectionError('<urllib3.connection.HTTPConnection object at 0x7d2fa73ce3f0>: Failed to establish a new connection: [Errno 111] Connection refused'))
Error in VaultConfigSettingsSource: Vault error: HTTPConnectionPool(host='127.0.0.1', port=8200): Max retries exceeded with url: /v1/auth/token/lookup-self (Caused by NewConnectionError('<urllib3.connection.HTTPConnection object at 0x7d2fa75d94c0>: Failed to establish a new connection: [Errno 111] Connection refused'))
Error in VaultConfigSettingsSource: Vault error: HTTPConnectionPool(host='127.0.0.1', port=8200): Max retries exceeded with url: /v1/auth/token/lookup-self (Caused by NewConnectionError('<urllib3.connection.HTTPConnection object at 0x7d2fa75e5dc0>: Failed to establish a new connection: [Errno 111] Connection refused'))
Error in VaultConfigSettingsSource: Vault error: HTTPConnectionPool(host='127.0.0.1', port=8200): Max retries exceeded with url: /v1/auth/token/lookup-self (Caused by NewConnectionError('<urllib3.connection.HTTPConnection object at 0x7d2fa73cdf10>: Failed to establish a new connection: [Errno 111] Connection refused'))
Error in VaultConfigSettingsSource: Vault error: HTTPConnectionPool(host='127.0.0.1', port=8200): Max retries exceeded with url: /v1/auth/token/lookup-self (Caused by NewConnectionError('<urllib3.connection.HTTPConnection object at 0x7d2fa74457c0>: Failed to establish a new connection: [Errno 111] Connection refused'))
Error in VaultConfigSettingsSource: Vault error: HTTPConnectionPool(host='127.0.0.1', port=8200): Max retries exceeded with url: /v1/auth/token/lookup-self (Caused by NewConnectionError('<urllib3.connection.HTTPConnection object at 0x7d2fa75da720>: Failed to establish a new connection: [Errno 111] Connection refused'))
Error in VaultConfigSettingsSource: Vault error: HTTPConnectionPool(host='127.0.0.1', port=8200): Max retries exceeded with url: /v1/auth/token/lookup-self (Caused by NewConnectionError('<urllib3.connection.HTTPConnection object at 0x7d2fa75e4d40>: Failed to establish a new connection: [Errno 111] Connection refused'))
2025-02-26 14:10:15,379 INFO sqlalchemy.engine.Engine select pg_catalog.version()
2025-02-26 14:10:15,379 INFO sqlalchemy.engine.Engine [raw sql] ()
2025-02-26 14:10:15,380 INFO sqlalchemy.engine.Engine select current_schema()
2025-02-26 14:10:15,381 INFO sqlalchemy.engine.Engine [raw sql] ()
2025-02-26 14:10:15,382 INFO sqlalchemy.engine.Engine show standard_conforming_strings
2025-02-26 14:10:15,382 INFO sqlalchemy.engine.Engine [raw sql] ()
2025-02-26 14:10:15,895 INFO sqlalchemy.engine.Engine select pg_catalog.version()
2025-02-26 14:10:15,895 INFO sqlalchemy.engine.Engine [raw sql] {}
2025-02-26 14:10:15,895 INFO sqlalchemy.engine.Engine select current_schema()
2025-02-26 14:10:15,895 INFO sqlalchemy.engine.Engine [raw sql] {}
2025-02-26 14:10:15,896 INFO sqlalchemy.engine.Engine show standard_conforming_strings
2025-02-26 14:10:15,896 INFO sqlalchemy.engine.Engine [raw sql] {}
2025-02-26 14:10:15,896 INFO sqlalchemy.engine.Engine BEGIN (implicit)
2025-02-26 14:10:15,899 INFO sqlalchemy.engine.Engine SELECT pg_catalog.pg_class.relname 
FROM pg_catalog.pg_class JOIN pg_catalog.pg_namespace ON pg_catalog.pg_namespace.oid = pg_catalog.pg_class.relnamespace 
WHERE pg_catalog.pg_class.relname = %(table_name)s AND pg_catalog.pg_class.relkind = ANY (ARRAY[%(param_1)s, %(param_2)s, %(param_3)s, %(param_4)s, %(param_5)s]) AND pg_catalog.pg_table_is_visible(pg_catalog.pg_class.oid) AND pg_catalog.pg_namespace.nspname != %(nspname_1)s
2025-02-26 14:10:15,899 INFO sqlalchemy.engine.Engine [generated in 0.00036s] {'table_name': 'apscheduler_jobs', 'param_1': 'r', 'param_2': 'p', 'param_3': 'f', 'param_4': 'v', 'param_5': 'm', 'nspname_1': 'pg_catalog'}
2025-02-26 14:10:15,900 INFO sqlalchemy.engine.Engine COMMIT
2025-02-26 14:10:15,901 INFO sqlalchemy.engine.Engine BEGIN (implicit)
2025-02-26 14:10:15,902 INFO sqlalchemy.engine.Engine INSERT INTO apscheduler_jobs (id, next_run_time, job_state) VALUES (%(id)s, %(next_run_time)s, %(job_state)s)
2025-02-26 14:10:15,903 INFO sqlalchemy.engine.Engine [generated in 0.00039s] {'id': 'check_all_services_job', 'next_run_time': 1740571814.089371, 'job_state': <psycopg2.extensions.Binary object at 0x7d2f8f4e4930>}
2025-02-26 14:10:15,907 INFO sqlalchemy.engine.Engine ROLLBACK
2025-02-26 14:10:15,907 INFO sqlalchemy.engine.Engine BEGIN (implicit)
2025-02-26 14:10:15,908 INFO sqlalchemy.engine.Engine UPDATE apscheduler_jobs SET next_run_time=%(next_run_time)s, job_state=%(job_state)s WHERE apscheduler_jobs.id = %(id_1)s
2025-02-26 14:10:15,909 INFO sqlalchemy.engine.Engine [generated in 0.00043s] {'next_run_time': 1740571814.089371, 'job_state': <psycopg2.extensions.Binary object at 0x7d2f8f4e50b0>, 'id_1': 'check_all_services_job'}
2025-02-26 14:10:15,912 INFO sqlalchemy.engine.Engine COMMIT
2025-02-26 14:10:15,939 INFO sqlalchemy.engine.Engine BEGIN (implicit)
2025-02-26 14:10:15,939 INFO sqlalchemy.engine.Engine SELECT apscheduler_jobs.id, apscheduler_jobs.job_state 
FROM apscheduler_jobs 
WHERE apscheduler_jobs.next_run_time <= %(next_run_time_1)s ORDER BY apscheduler_jobs.next_run_time
2025-02-26 14:10:15,939 INFO sqlalchemy.engine.Engine [generated in 0.00019s] {'next_run_time_1': 1740568215.938894}
2025-02-26 14:10:15,941 INFO sqlalchemy.engine.Engine COMMIT
2025-02-26 14:10:15,941 INFO sqlalchemy.engine.Engine BEGIN (implicit)
2025-02-26 14:10:15,943 INFO sqlalchemy.engine.Engine SELECT apscheduler_jobs.next_run_time 
FROM apscheduler_jobs 
WHERE apscheduler_jobs.next_run_time IS NOT NULL ORDER BY apscheduler_jobs.next_run_time 
 LIMIT %(param_1)s
2025-02-26 14:10:15,943 INFO sqlalchemy.engine.Engine [generated in 0.00100s] {'param_1': 1}
2025-02-26 14:10:15,945 INFO sqlalchemy.engine.Engine COMMIT
INFO:     Application startup complete.
14:10:22.722 | INFO    | prefect.engine - View at http://localhost:4200/runs/flow-run/ea7c7c76-a375-4d63-87af-c8c932fefa2c
14:10:22.774 | INFO    | Flow run 'deft-lyrebird' - Beginning flow run 'deft-lyrebird' for flow 'send-notification-workflow'
14:10:22.779 | INFO    | Flow run 'deft-lyrebird' - View at http://localhost:4200/runs/flow-run/ea7c7c76-a375-4d63-87af-c8c932fefa2c
14:10:22.861 | INFO    | Task run 'send-notification-bf9' - Finished in state Completed()
14:10:22.944 | INFO    | Flow run 'deft-lyrebird' - Finished in state Completed()
WARNING:  StatReload detected changes in 'app/infra/clients/stream.py'. Reloading...
INFO:     Started server process [1242697]
INFO:     Waiting for application startup.
Error in VaultConfigSettingsSource: Vault error: HTTPConnectionPool(host='127.0.0.1', port=8200): Max retries exceeded with url: /v1/auth/token/lookup-self (Caused by NewConnectionError('<urllib3.connection.HTTPConnection object at 0x794a23b7fdd0>: Failed to establish a new connection: [Errno 111] Connection refused'))
Error in VaultConfigSettingsSource: Vault error: HTTPConnectionPool(host='127.0.0.1', port=8200): Max retries exceeded with url: /v1/auth/token/lookup-self (Caused by NewConnectionError('<urllib3.connection.HTTPConnection object at 0x794a23954aa0>: Failed to establish a new connection: [Errno 111] Connection refused'))
Error in VaultConfigSettingsSource: Vault error: HTTPConnectionPool(host='127.0.0.1', port=8200): Max retries exceeded with url: /v1/auth/token/lookup-self (Caused by NewConnectionError('<urllib3.connection.HTTPConnection object at 0x794a239798b0>: Failed to establish a new connection: [Errno 111] Connection refused'))
Error in VaultConfigSettingsSource: Vault error: HTTPConnectionPool(host='127.0.0.1', port=8200): Max retries exceeded with url: /v1/auth/token/lookup-self (Caused by NewConnectionError('<urllib3.connection.HTTPConnection object at 0x794a23955730>: Failed to establish a new connection: [Errno 111] Connection refused'))
Error in VaultConfigSettingsSource: Vault error: HTTPConnectionPool(host='127.0.0.1', port=8200): Max retries exceeded with url: /v1/auth/token/lookup-self (Caused by NewConnectionError('<urllib3.connection.HTTPConnection object at 0x794a239811f0>: Failed to establish a new connection: [Errno 111] Connection refused'))
Error in VaultConfigSettingsSource: Vault error: HTTPConnectionPool(host='127.0.0.1', port=8200): Max retries exceeded with url: /v1/auth/token/lookup-self (Caused by NewConnectionError('<urllib3.connection.HTTPConnection object at 0x794a23979eb0>: Failed to establish a new connection: [Errno 111] Connection refused'))
Error in VaultConfigSettingsSource: Vault error: HTTPConnectionPool(host='127.0.0.1', port=8200): Max retries exceeded with url: /v1/auth/token/lookup-self (Caused by NewConnectionError('<urllib3.connection.HTTPConnection object at 0x794a237549e0>: Failed to establish a new connection: [Errno 111] Connection refused'))
Error in VaultConfigSettingsSource: Vault error: HTTPConnectionPool(host='127.0.0.1', port=8200): Max retries exceeded with url: /v1/auth/token/lookup-self (Caused by NewConnectionError('<urllib3.connection.HTTPConnection object at 0x794a23957410>: Failed to establish a new connection: [Errno 111] Connection refused'))
Error in VaultConfigSettingsSource: Vault error: HTTPConnectionPool(host='127.0.0.1', port=8200): Max retries exceeded with url: /v1/auth/token/lookup-self (Caused by NewConnectionError('<urllib3.connection.HTTPConnection object at 0x794a2397ba70>: Failed to establish a new connection: [Errno 111] Connection refused'))
Error in VaultConfigSettingsSource: Vault error: HTTPConnectionPool(host='127.0.0.1', port=8200): Max retries exceeded with url: /v1/auth/token/lookup-self (Caused by NewConnectionError('<urllib3.connection.HTTPConnection object at 0x794a23981fa0>: Failed to establish a new connection: [Errno 111] Connection refused'))
Error in VaultConfigSettingsSource: Vault error: HTTPConnectionPool(host='127.0.0.1', port=8200): Max retries exceeded with url: /v1/auth/token/lookup-self (Caused by NewConnectionError('<urllib3.connection.HTTPConnection object at 0x794a23757050>: Failed to establish a new connection: [Errno 111] Connection refused'))
Error in VaultConfigSettingsSource: Vault error: HTTPConnectionPool(host='127.0.0.1', port=8200): Max retries exceeded with url: /v1/auth/token/lookup-self (Caused by NewConnectionError('<urllib3.connection.HTTPConnection object at 0x794a23956b70>: Failed to establish a new connection: [Errno 111] Connection refused'))
Error in VaultConfigSettingsSource: Vault error: HTTPConnectionPool(host='127.0.0.1', port=8200): Max retries exceeded with url: /v1/auth/token/lookup-self (Caused by NewConnectionError('<urllib3.connection.HTTPConnection object at 0x794a239806e0>: Failed to establish a new connection: [Errno 111] Connection refused'))
Error in VaultConfigSettingsSource: Vault error: HTTPConnectionPool(host='127.0.0.1', port=8200): Max retries exceeded with url: /v1/auth/token/lookup-self (Caused by NewConnectionError('<urllib3.connection.HTTPConnection object at 0x794a23978fb0>: Failed to establish a new connection: [Errno 111] Connection refused'))
Error in VaultConfigSettingsSource: Vault error: HTTPConnectionPool(host='127.0.0.1', port=8200): Max retries exceeded with url: /v1/auth/token/lookup-self (Caused by NewConnectionError('<urllib3.connection.HTTPConnection object at 0x794a237c5520>: Failed to establish a new connection: [Errno 111] Connection refused'))
Error in VaultConfigSettingsSource: Vault error: HTTPConnectionPool(host='127.0.0.1', port=8200): Max retries exceeded with url: /v1/auth/token/lookup-self (Caused by NewConnectionError('<urllib3.connection.HTTPConnection object at 0x794a23757f80>: Failed to establish a new connection: [Errno 111] Connection refused'))
2025-02-26 14:12:05,084 INFO sqlalchemy.engine.Engine select pg_catalog.version()
2025-02-26 14:12:05,084 INFO sqlalchemy.engine.Engine [raw sql] ()
2025-02-26 14:12:05,086 INFO sqlalchemy.engine.Engine select current_schema()
2025-02-26 14:12:05,086 INFO sqlalchemy.engine.Engine [raw sql] ()
2025-02-26 14:12:05,087 INFO sqlalchemy.engine.Engine show standard_conforming_strings
2025-02-26 14:12:05,087 INFO sqlalchemy.engine.Engine [raw sql] ()
2025-02-26 14:12:05,538 INFO sqlalchemy.engine.Engine select pg_catalog.version()
2025-02-26 14:12:05,539 INFO sqlalchemy.engine.Engine [raw sql] {}
2025-02-26 14:12:05,539 INFO sqlalchemy.engine.Engine select current_schema()
2025-02-26 14:12:05,539 INFO sqlalchemy.engine.Engine [raw sql] {}
2025-02-26 14:12:05,539 INFO sqlalchemy.engine.Engine show standard_conforming_strings
2025-02-26 14:12:05,539 INFO sqlalchemy.engine.Engine [raw sql] {}
2025-02-26 14:12:05,540 INFO sqlalchemy.engine.Engine BEGIN (implicit)
2025-02-26 14:12:05,544 INFO sqlalchemy.engine.Engine SELECT pg_catalog.pg_class.relname 
FROM pg_catalog.pg_class JOIN pg_catalog.pg_namespace ON pg_catalog.pg_namespace.oid = pg_catalog.pg_class.relnamespace 
WHERE pg_catalog.pg_class.relname = %(table_name)s AND pg_catalog.pg_class.relkind = ANY (ARRAY[%(param_1)s, %(param_2)s, %(param_3)s, %(param_4)s, %(param_5)s]) AND pg_catalog.pg_table_is_visible(pg_catalog.pg_class.oid) AND pg_catalog.pg_namespace.nspname != %(nspname_1)s
2025-02-26 14:12:05,544 INFO sqlalchemy.engine.Engine [generated in 0.00210s] {'table_name': 'apscheduler_jobs', 'param_1': 'r', 'param_2': 'p', 'param_3': 'f', 'param_4': 'v', 'param_5': 'm', 'nspname_1': 'pg_catalog'}
2025-02-26 14:12:05,552 INFO sqlalchemy.engine.Engine COMMIT
2025-02-26 14:12:05,552 INFO sqlalchemy.engine.Engine BEGIN (implicit)
2025-02-26 14:12:05,554 INFO sqlalchemy.engine.Engine INSERT INTO apscheduler_jobs (id, next_run_time, job_state) VALUES (%(id)s, %(next_run_time)s, %(job_state)s)
2025-02-26 14:12:05,554 INFO sqlalchemy.engine.Engine [generated in 0.00090s] {'id': 'check_all_services_job', 'next_run_time': 1740571923.800377, 'job_state': <psycopg2.extensions.Binary object at 0x794a0b78cc00>}
2025-02-26 14:12:05,558 INFO sqlalchemy.engine.Engine ROLLBACK
2025-02-26 14:12:05,559 INFO sqlalchemy.engine.Engine BEGIN (implicit)
2025-02-26 14:12:05,560 INFO sqlalchemy.engine.Engine UPDATE apscheduler_jobs SET next_run_time=%(next_run_time)s, job_state=%(job_state)s WHERE apscheduler_jobs.id = %(id_1)s
2025-02-26 14:12:05,560 INFO sqlalchemy.engine.Engine [generated in 0.00026s] {'next_run_time': 1740571923.800377, 'job_state': <psycopg2.extensions.Binary object at 0x794a0b78d590>, 'id_1': 'check_all_services_job'}
2025-02-26 14:12:05,564 INFO sqlalchemy.engine.Engine COMMIT
2025-02-26 14:12:05,594 INFO sqlalchemy.engine.Engine BEGIN (implicit)
2025-02-26 14:12:05,595 INFO sqlalchemy.engine.Engine SELECT apscheduler_jobs.id, apscheduler_jobs.job_state 
FROM apscheduler_jobs 
WHERE apscheduler_jobs.next_run_time <= %(next_run_time_1)s ORDER BY apscheduler_jobs.next_run_time
2025-02-26 14:12:05,596 INFO sqlalchemy.engine.Engine [generated in 0.00040s] {'next_run_time_1': 1740568325.59387}
2025-02-26 14:12:05,597 INFO sqlalchemy.engine.Engine COMMIT
2025-02-26 14:12:05,599 INFO sqlalchemy.engine.Engine BEGIN (implicit)
2025-02-26 14:12:05,600 INFO sqlalchemy.engine.Engine SELECT apscheduler_jobs.next_run_time 
FROM apscheduler_jobs 
WHERE apscheduler_jobs.next_run_time IS NOT NULL ORDER BY apscheduler_jobs.next_run_time 
 LIMIT %(param_1)s
2025-02-26 14:12:05,600 INFO sqlalchemy.engine.Engine [generated in 0.00024s] {'param_1': 1}
2025-02-26 14:12:05,601 INFO sqlalchemy.engine.Engine COMMIT
INFO:     Application startup complete.
WARNING:  StatReload detected changes in 'app/background_tasks/tasks.py'. Reloading...
INFO:     Shutting down
INFO:     Waiting for application shutdown.
INFO:     Application shutdown complete.
INFO:     Finished server process [1242697]
INFO:     Started server process [1243291]
INFO:     Waiting for application startup.
Error in VaultConfigSettingsSource: Vault error: HTTPConnectionPool(host='127.0.0.1', port=8200): Max retries exceeded with url: /v1/auth/token/lookup-self (Caused by NewConnectionError('<urllib3.connection.HTTPConnection object at 0x7ea09c773710>: Failed to establish a new connection: [Errno 111] Connection refused'))
Error in VaultConfigSettingsSource: Vault error: HTTPConnectionPool(host='127.0.0.1', port=8200): Max retries exceeded with url: /v1/auth/token/lookup-self (Caused by NewConnectionError('<urllib3.connection.HTTPConnection object at 0x7ea09c803e00>: Failed to establish a new connection: [Errno 111] Connection refused'))
Error in VaultConfigSettingsSource: Vault error: HTTPConnectionPool(host='127.0.0.1', port=8200): Max retries exceeded with url: /v1/auth/token/lookup-self (Caused by NewConnectionError('<urllib3.connection.HTTPConnection object at 0x7ea09c65e6c0>: Failed to establish a new connection: [Errno 111] Connection refused'))
Error in VaultConfigSettingsSource: Vault error: HTTPConnectionPool(host='127.0.0.1', port=8200): Max retries exceeded with url: /v1/auth/token/lookup-self (Caused by NewConnectionError('<urllib3.connection.HTTPConnection object at 0x7ea09c837cb0>: Failed to establish a new connection: [Errno 111] Connection refused'))
Error in VaultConfigSettingsSource: Vault error: HTTPConnectionPool(host='127.0.0.1', port=8200): Max retries exceeded with url: /v1/auth/token/lookup-self (Caused by NewConnectionError('<urllib3.connection.HTTPConnection object at 0x7ea09c6d1ca0>: Failed to establish a new connection: [Errno 111] Connection refused'))
Error in VaultConfigSettingsSource: Vault error: HTTPConnectionPool(host='127.0.0.1', port=8200): Max retries exceeded with url: /v1/auth/token/lookup-self (Caused by NewConnectionError('<urllib3.connection.HTTPConnection object at 0x7ea09c7736b0>: Failed to establish a new connection: [Errno 111] Connection refused'))
Error in VaultConfigSettingsSource: Vault error: HTTPConnectionPool(host='127.0.0.1', port=8200): Max retries exceeded with url: /v1/auth/token/lookup-self (Caused by NewConnectionError('<urllib3.connection.HTTPConnection object at 0x7ea09c6f4080>: Failed to establish a new connection: [Errno 111] Connection refused'))
Error in VaultConfigSettingsSource: Vault error: HTTPConnectionPool(host='127.0.0.1', port=8200): Max retries exceeded with url: /v1/auth/token/lookup-self (Caused by NewConnectionError('<urllib3.connection.HTTPConnection object at 0x7ea09c6f9070>: Failed to establish a new connection: [Errno 111] Connection refused'))
Error in VaultConfigSettingsSource: Vault error: HTTPConnectionPool(host='127.0.0.1', port=8200): Max retries exceeded with url: /v1/auth/token/lookup-self (Caused by NewConnectionError('<urllib3.connection.HTTPConnection object at 0x7ea09c65cda0>: Failed to establish a new connection: [Errno 111] Connection refused'))
Error in VaultConfigSettingsSource: Vault error: HTTPConnectionPool(host='127.0.0.1', port=8200): Max retries exceeded with url: /v1/auth/token/lookup-self (Caused by NewConnectionError('<urllib3.connection.HTTPConnection object at 0x7ea09c835940>: Failed to establish a new connection: [Errno 111] Connection refused'))
Error in VaultConfigSettingsSource: Vault error: HTTPConnectionPool(host='127.0.0.1', port=8200): Max retries exceeded with url: /v1/auth/token/lookup-self (Caused by NewConnectionError('<urllib3.connection.HTTPConnection object at 0x7ea09c6d0440>: Failed to establish a new connection: [Errno 111] Connection refused'))
Error in VaultConfigSettingsSource: Vault error: HTTPConnectionPool(host='127.0.0.1', port=8200): Max retries exceeded with url: /v1/auth/token/lookup-self (Caused by NewConnectionError('<urllib3.connection.HTTPConnection object at 0x7ea09c6f4da0>: Failed to establish a new connection: [Errno 111] Connection refused'))
Error in VaultConfigSettingsSource: Vault error: HTTPConnectionPool(host='127.0.0.1', port=8200): Max retries exceeded with url: /v1/auth/token/lookup-self (Caused by NewConnectionError('<urllib3.connection.HTTPConnection object at 0x7ea09c6f86b0>: Failed to establish a new connection: [Errno 111] Connection refused'))
Error in VaultConfigSettingsSource: Vault error: HTTPConnectionPool(host='127.0.0.1', port=8200): Max retries exceeded with url: /v1/auth/token/lookup-self (Caused by NewConnectionError('<urllib3.connection.HTTPConnection object at 0x7ea09c837200>: Failed to establish a new connection: [Errno 111] Connection refused'))
Error in VaultConfigSettingsSource: Vault error: HTTPConnectionPool(host='127.0.0.1', port=8200): Max retries exceeded with url: /v1/auth/token/lookup-self (Caused by NewConnectionError('<urllib3.connection.HTTPConnection object at 0x7ea09c541c70>: Failed to establish a new connection: [Errno 111] Connection refused'))
Error in VaultConfigSettingsSource: Vault error: HTTPConnectionPool(host='127.0.0.1', port=8200): Max retries exceeded with url: /v1/auth/token/lookup-self (Caused by NewConnectionError('<urllib3.connection.HTTPConnection object at 0x7ea09c65f470>: Failed to establish a new connection: [Errno 111] Connection refused'))
2025-02-26 14:12:35,323 INFO sqlalchemy.engine.Engine select pg_catalog.version()
2025-02-26 14:12:35,323 INFO sqlalchemy.engine.Engine [raw sql] ()
2025-02-26 14:12:35,325 INFO sqlalchemy.engine.Engine select current_schema()
2025-02-26 14:12:35,325 INFO sqlalchemy.engine.Engine [raw sql] ()
2025-02-26 14:12:35,327 INFO sqlalchemy.engine.Engine show standard_conforming_strings
2025-02-26 14:12:35,327 INFO sqlalchemy.engine.Engine [raw sql] ()
2025-02-26 14:12:35,873 INFO sqlalchemy.engine.Engine select pg_catalog.version()
2025-02-26 14:12:35,873 INFO sqlalchemy.engine.Engine [raw sql] {}
2025-02-26 14:12:35,874 INFO sqlalchemy.engine.Engine select current_schema()
2025-02-26 14:12:35,874 INFO sqlalchemy.engine.Engine [raw sql] {}
2025-02-26 14:12:35,874 INFO sqlalchemy.engine.Engine show standard_conforming_strings
2025-02-26 14:12:35,875 INFO sqlalchemy.engine.Engine [raw sql] {}
2025-02-26 14:12:35,875 INFO sqlalchemy.engine.Engine BEGIN (implicit)
2025-02-26 14:12:35,879 INFO sqlalchemy.engine.Engine SELECT pg_catalog.pg_class.relname 
FROM pg_catalog.pg_class JOIN pg_catalog.pg_namespace ON pg_catalog.pg_namespace.oid = pg_catalog.pg_class.relnamespace 
WHERE pg_catalog.pg_class.relname = %(table_name)s AND pg_catalog.pg_class.relkind = ANY (ARRAY[%(param_1)s, %(param_2)s, %(param_3)s, %(param_4)s, %(param_5)s]) AND pg_catalog.pg_table_is_visible(pg_catalog.pg_class.oid) AND pg_catalog.pg_namespace.nspname != %(nspname_1)s
2025-02-26 14:12:35,879 INFO sqlalchemy.engine.Engine [generated in 0.00077s] {'table_name': 'apscheduler_jobs', 'param_1': 'r', 'param_2': 'p', 'param_3': 'f', 'param_4': 'v', 'param_5': 'm', 'nspname_1': 'pg_catalog'}
2025-02-26 14:12:35,881 INFO sqlalchemy.engine.Engine COMMIT
2025-02-26 14:12:35,882 INFO sqlalchemy.engine.Engine BEGIN (implicit)
2025-02-26 14:12:35,885 INFO sqlalchemy.engine.Engine INSERT INTO apscheduler_jobs (id, next_run_time, job_state) VALUES (%(id)s, %(next_run_time)s, %(job_state)s)
2025-02-26 14:12:35,886 INFO sqlalchemy.engine.Engine [generated in 0.00121s] {'id': 'check_all_services_job', 'next_run_time': 1740571951.320192, 'job_state': <psycopg2.extensions.Binary object at 0x7ea085da75a0>}
2025-02-26 14:12:35,889 INFO sqlalchemy.engine.Engine ROLLBACK
2025-02-26 14:12:35,889 INFO sqlalchemy.engine.Engine BEGIN (implicit)
2025-02-26 14:12:35,890 INFO sqlalchemy.engine.Engine UPDATE apscheduler_jobs SET next_run_time=%(next_run_time)s, job_state=%(job_state)s WHERE apscheduler_jobs.id = %(id_1)s
2025-02-26 14:12:35,891 INFO sqlalchemy.engine.Engine [generated in 0.00081s] {'next_run_time': 1740571951.320192, 'job_state': <psycopg2.extensions.Binary object at 0x7ea08410aa30>, 'id_1': 'check_all_services_job'}
2025-02-26 14:12:35,892 INFO sqlalchemy.engine.Engine COMMIT
2025-02-26 14:12:35,962 INFO sqlalchemy.engine.Engine BEGIN (implicit)
2025-02-26 14:12:35,963 INFO sqlalchemy.engine.Engine SELECT apscheduler_jobs.id, apscheduler_jobs.job_state 
FROM apscheduler_jobs 
WHERE apscheduler_jobs.next_run_time <= %(next_run_time_1)s ORDER BY apscheduler_jobs.next_run_time
2025-02-26 14:12:35,963 INFO sqlalchemy.engine.Engine [generated in 0.00025s] {'next_run_time_1': 1740568355.961931}
2025-02-26 14:12:35,967 INFO sqlalchemy.engine.Engine COMMIT
2025-02-26 14:12:35,968 INFO sqlalchemy.engine.Engine BEGIN (implicit)
2025-02-26 14:12:35,972 INFO sqlalchemy.engine.Engine SELECT apscheduler_jobs.next_run_time 
FROM apscheduler_jobs 
WHERE apscheduler_jobs.next_run_time IS NOT NULL ORDER BY apscheduler_jobs.next_run_time 
 LIMIT %(param_1)s
2025-02-26 14:12:35,974 INFO sqlalchemy.engine.Engine [generated in 0.00261s] {'param_1': 1}
2025-02-26 14:12:35,975 INFO sqlalchemy.engine.Engine COMMIT
INFO:     Application startup complete.
