[I 250210 21:58:12 command:168] Visit me at http://0.0.0.0:8888
[I 250210 21:58:12 command:176] Broker: redis://:**@localhost:6379/3
[I 250210 21:58:12 command:177] Registered tasks: 
    ['celery.accumulate',
     'celery.backend_cleanup',
     'celery.chain',
     'celery.chord',
     'celery.chord_unlock',
     'celery.chunks',
     'celery.group',
     'celery.map',
     'celery.starmap',
     'check_services_health',
     'process_order_workflow',
     'send_mail',
     'send_requests_for_create_order',
     'send_requests_for_get_result',
     'send_result_to_gd']
[I 250210 21:58:12 mixins:228] Connected to redis://:**@localhost:6379/3
[W 250210 21:58:14 inspector:44] Inspect method stats failed
[W 250210 21:58:14 inspector:44] Inspect method registered failed
[W 250210 21:58:14 inspector:44] Inspect method scheduled failed
[W 250210 21:58:14 inspector:44] Inspect method revoked failed
[W 250210 21:58:14 inspector:44] Inspect method active_queues failed
[W 250210 21:58:14 inspector:44] Inspect method conf failed
[W 250210 21:58:14 inspector:44] Inspect method active failed
[W 250210 21:58:14 inspector:44] Inspect method reserved failed
Error in VaultConfigSettingsSource: Vault error: HTTPConnectionPool(host='127.0.0.1', port=8200): Max retries exceeded with url: /v1/auth/token/lookup-self (Caused by NewConnectionError('<urllib3.connection.HTTPConnection object at 0x7cb74a8ca840>: Failed to establish a new connection: [Errno 111] Connection refused'))
Error in VaultConfigSettingsSource: Vault error: HTTPConnectionPool(host='127.0.0.1', port=8200): Max retries exceeded with url: /v1/auth/token/lookup-self (Caused by NewConnectionError('<urllib3.connection.HTTPConnection object at 0x7cb74a8fe960>: Failed to establish a new connection: [Errno 111] Connection refused'))
Error in VaultConfigSettingsSource: Vault error: HTTPConnectionPool(host='127.0.0.1', port=8200): Max retries exceeded with url: /v1/auth/token/lookup-self (Caused by NewConnectionError('<urllib3.connection.HTTPConnection object at 0x7cb74a6c9dc0>: Failed to establish a new connection: [Errno 111] Connection refused'))
Error in VaultConfigSettingsSource: Vault error: HTTPConnectionPool(host='127.0.0.1', port=8200): Max retries exceeded with url: /v1/auth/token/lookup-self (Caused by NewConnectionError('<urllib3.connection.HTTPConnection object at 0x7cb74a6d65a0>: Failed to establish a new connection: [Errno 111] Connection refused'))
Error in VaultConfigSettingsSource: Vault error: HTTPConnectionPool(host='127.0.0.1', port=8200): Max retries exceeded with url: /v1/auth/token/lookup-self (Caused by NewConnectionError('<urllib3.connection.HTTPConnection object at 0x7cb74a8ffe60>: Failed to establish a new connection: [Errno 111] Connection refused'))
Error in VaultConfigSettingsSource: Vault error: HTTPConnectionPool(host='127.0.0.1', port=8200): Max retries exceeded with url: /v1/auth/token/lookup-self (Caused by NewConnectionError('<urllib3.connection.HTTPConnection object at 0x7cb74a6caab0>: Failed to establish a new connection: [Errno 111] Connection refused'))
Error in VaultConfigSettingsSource: Vault error: HTTPConnectionPool(host='127.0.0.1', port=8200): Max retries exceeded with url: /v1/auth/token/lookup-self (Caused by NewConnectionError('<urllib3.connection.HTTPConnection object at 0x7cb74a6d7830>: Failed to establish a new connection: [Errno 111] Connection refused'))
Error in VaultConfigSettingsSource: Vault error: HTTPConnectionPool(host='127.0.0.1', port=8200): Max retries exceeded with url: /v1/auth/token/lookup-self (Caused by NewConnectionError('<urllib3.connection.HTTPConnection object at 0x7cb74a8caa80>: Failed to establish a new connection: [Errno 111] Connection refused'))
Error in VaultConfigSettingsSource: Vault error: HTTPConnectionPool(host='127.0.0.1', port=8200): Max retries exceeded with url: /v1/auth/token/lookup-self (Caused by NewConnectionError('<urllib3.connection.HTTPConnection object at 0x7cb74a6c93a0>: Failed to establish a new connection: [Errno 111] Connection refused'))
Error in VaultConfigSettingsSource: Vault error: HTTPConnectionPool(host='127.0.0.1', port=8200): Max retries exceeded with url: /v1/auth/token/lookup-self (Caused by NewConnectionError('<urllib3.connection.HTTPConnection object at 0x7cb74a6d4800>: Failed to establish a new connection: [Errno 111] Connection refused'))
Error in VaultConfigSettingsSource: Vault error: HTTPConnectionPool(host='127.0.0.1', port=8200): Max retries exceeded with url: /v1/auth/token/lookup-self (Caused by NewConnectionError('<urllib3.connection.HTTPConnection object at 0x7cb74a8ff4d0>: Failed to establish a new connection: [Errno 111] Connection refused'))
Error in VaultConfigSettingsSource: Vault error: HTTPConnectionPool(host='127.0.0.1', port=8200): Max retries exceeded with url: /v1/auth/token/lookup-self (Caused by NewConnectionError('<urllib3.connection.HTTPConnection object at 0x7cb74a739d30>: Failed to establish a new connection: [Errno 111] Connection refused'))
Error in VaultConfigSettingsSource: Vault error: HTTPConnectionPool(host='127.0.0.1', port=8200): Max retries exceeded with url: /v1/auth/token/lookup-self (Caused by NewConnectionError('<urllib3.connection.HTTPConnection object at 0x7cb74a6cafc0>: Failed to establish a new connection: [Errno 111] Connection refused'))
[I 250210 22:01:47 command:168] Visit me at http://0.0.0.0:8888
[I 250210 22:01:47 command:176] Broker: redis://:**@localhost:6379/3
[I 250210 22:01:47 command:177] Registered tasks: 
    ['celery.accumulate',
     'celery.backend_cleanup',
     'celery.chain',
     'celery.chord',
     'celery.chord_unlock',
     'celery.chunks',
     'celery.group',
     'celery.map',
     'celery.starmap',
     'check_services_health',
     'process_order_workflow',
     'send_mail',
     'send_requests_for_create_order',
     'send_requests_for_get_result',
     'send_result_to_gd']
[I 250210 22:01:47 mixins:228] Connected to redis://:**@localhost:6379/3
[W 250210 22:01:48 inspector:44] Inspect method registered failed
[W 250210 22:01:48 inspector:44] Inspect method active_queues failed
[W 250210 22:01:48 inspector:44] Inspect method conf failed
[W 250210 22:01:48 inspector:44] Inspect method stats failed
[W 250210 22:01:48 inspector:44] Inspect method scheduled failed
[W 250210 22:01:48 inspector:44] Inspect method reserved failed
[W 250210 22:01:48 inspector:44] Inspect method active failed
[W 250210 22:01:48 inspector:44] Inspect method revoked failed
Error in VaultConfigSettingsSource: Vault error: HTTPConnectionPool(host='127.0.0.1', port=8200): Max retries exceeded with url: /v1/auth/token/lookup-self (Caused by NewConnectionError('<urllib3.connection.HTTPConnection object at 0x7659aebef470>: Failed to establish a new connection: [Errno 111] Connection refused'))
Error in VaultConfigSettingsSource: Vault error: HTTPConnectionPool(host='127.0.0.1', port=8200): Max retries exceeded with url: /v1/auth/token/lookup-self (Caused by NewConnectionError('<urllib3.connection.HTTPConnection object at 0x7659ae59e930>: Failed to establish a new connection: [Errno 111] Connection refused'))
Error in VaultConfigSettingsSource: Vault error: HTTPConnectionPool(host='127.0.0.1', port=8200): Max retries exceeded with url: /v1/auth/token/lookup-self (Caused by NewConnectionError('<urllib3.connection.HTTPConnection object at 0x7659ae36d910>: Failed to establish a new connection: [Errno 111] Connection refused'))
Error in VaultConfigSettingsSource: Vault error: HTTPConnectionPool(host='127.0.0.1', port=8200): Max retries exceeded with url: /v1/auth/token/lookup-self (Caused by NewConnectionError('<urllib3.connection.HTTPConnection object at 0x7659ae5b65d0>: Failed to establish a new connection: [Errno 111] Connection refused'))
Error in VaultConfigSettingsSource: Vault error: HTTPConnectionPool(host='127.0.0.1', port=8200): Max retries exceeded with url: /v1/auth/token/lookup-self (Caused by NewConnectionError('<urllib3.connection.HTTPConnection object at 0x7659ae59e780>: Failed to establish a new connection: [Errno 111] Connection refused'))
Error in VaultConfigSettingsSource: Vault error: HTTPConnectionPool(host='127.0.0.1', port=8200): Max retries exceeded with url: /v1/auth/token/lookup-self (Caused by NewConnectionError('<urllib3.connection.HTTPConnection object at 0x7659ae36eae0>: Failed to establish a new connection: [Errno 111] Connection refused'))
Error in VaultConfigSettingsSource: Vault error: HTTPConnectionPool(host='127.0.0.1', port=8200): Max retries exceeded with url: /v1/auth/token/lookup-self (Caused by NewConnectionError('<urllib3.connection.HTTPConnection object at 0x7659ae5b6ab0>: Failed to establish a new connection: [Errno 111] Connection refused'))
Error in VaultConfigSettingsSource: Vault error: HTTPConnectionPool(host='127.0.0.1', port=8200): Max retries exceeded with url: /v1/auth/token/lookup-self (Caused by NewConnectionError('<urllib3.connection.HTTPConnection object at 0x7659ae56da00>: Failed to establish a new connection: [Errno 111] Connection refused'))
Error in VaultConfigSettingsSource: Vault error: HTTPConnectionPool(host='127.0.0.1', port=8200): Max retries exceeded with url: /v1/auth/token/lookup-self (Caused by NewConnectionError('<urllib3.connection.HTTPConnection object at 0x7659ae36d6d0>: Failed to establish a new connection: [Errno 111] Connection refused'))
Error in VaultConfigSettingsSource: Vault error: HTTPConnectionPool(host='127.0.0.1', port=8200): Max retries exceeded with url: /v1/auth/token/lookup-self (Caused by NewConnectionError('<urllib3.connection.HTTPConnection object at 0x7659ae5b7bc0>: Failed to establish a new connection: [Errno 111] Connection refused'))
Error in VaultConfigSettingsSource: Vault error: HTTPConnectionPool(host='127.0.0.1', port=8200): Max retries exceeded with url: /v1/auth/token/lookup-self (Caused by NewConnectionError('<urllib3.connection.HTTPConnection object at 0x7659ae59f200>: Failed to establish a new connection: [Errno 111] Connection refused'))
Error in VaultConfigSettingsSource: Vault error: HTTPConnectionPool(host='127.0.0.1', port=8200): Max retries exceeded with url: /v1/auth/token/lookup-self (Caused by NewConnectionError('<urllib3.connection.HTTPConnection object at 0x7659ae36e450>: Failed to establish a new connection: [Errno 111] Connection refused'))
Error in VaultConfigSettingsSource: Vault error: HTTPConnectionPool(host='127.0.0.1', port=8200): Max retries exceeded with url: /v1/auth/token/lookup-self (Caused by NewConnectionError('<urllib3.connection.HTTPConnection object at 0x7659ae3e1970>: Failed to establish a new connection: [Errno 111] Connection refused'))
[I 250210 22:07:06 command:168] Visit me at http://0.0.0.0:8888
[I 250210 22:07:06 command:176] Broker: redis://:**@localhost:6379/3
[I 250210 22:07:06 command:177] Registered tasks: 
    ['celery.accumulate',
     'celery.backend_cleanup',
     'celery.chain',
     'celery.chord',
     'celery.chord_unlock',
     'celery.chunks',
     'celery.group',
     'celery.map',
     'celery.starmap',
     'check_services_health',
     'process_order_workflow',
     'send_mail',
     'send_requests_for_create_order',
     'send_requests_for_get_result',
     'send_result_to_gd']
[I 250210 22:07:06 mixins:228] Connected to redis://:**@localhost:6379/3
[W 250210 22:07:08 inspector:44] Inspect method revoked failed
[W 250210 22:07:08 inspector:44] Inspect method registered failed
[W 250210 22:07:08 inspector:44] Inspect method conf failed
[W 250210 22:07:08 inspector:44] Inspect method scheduled failed
[W 250210 22:07:08 inspector:44] Inspect method stats failed
[W 250210 22:07:08 inspector:44] Inspect method active_queues failed
[W 250210 22:07:08 inspector:44] Inspect method reserved failed
[W 250210 22:07:08 inspector:44] Inspect method active failed
Error in VaultConfigSettingsSource: Vault error: HTTPConnectionPool(host='127.0.0.1', port=8200): Max retries exceeded with url: /v1/auth/token/lookup-self (Caused by NewConnectionError('<urllib3.connection.HTTPConnection object at 0x76a23527fbf0>: Failed to establish a new connection: [Errno 111] Connection refused'))
Error in VaultConfigSettingsSource: Vault error: HTTPConnectionPool(host='127.0.0.1', port=8200): Max retries exceeded with url: /v1/auth/token/lookup-self (Caused by NewConnectionError('<urllib3.connection.HTTPConnection object at 0x76a234fe6e70>: Failed to establish a new connection: [Errno 111] Connection refused'))
Error in VaultConfigSettingsSource: Vault error: HTTPConnectionPool(host='127.0.0.1', port=8200): Max retries exceeded with url: /v1/auth/token/lookup-self (Caused by NewConnectionError('<urllib3.connection.HTTPConnection object at 0x76a234dadbb0>: Failed to establish a new connection: [Errno 111] Connection refused'))
Error in VaultConfigSettingsSource: Vault error: HTTPConnectionPool(host='127.0.0.1', port=8200): Max retries exceeded with url: /v1/auth/token/lookup-self (Caused by NewConnectionError('<urllib3.connection.HTTPConnection object at 0x76a234db24b0>: Failed to establish a new connection: [Errno 111] Connection refused'))
Error in VaultConfigSettingsSource: Vault error: HTTPConnectionPool(host='127.0.0.1', port=8200): Max retries exceeded with url: /v1/auth/token/lookup-self (Caused by NewConnectionError('<urllib3.connection.HTTPConnection object at 0x76a234fe7e30>: Failed to establish a new connection: [Errno 111] Connection refused'))
Error in VaultConfigSettingsSource: Vault error: HTTPConnectionPool(host='127.0.0.1', port=8200): Max retries exceeded with url: /v1/auth/token/lookup-self (Caused by NewConnectionError('<urllib3.connection.HTTPConnection object at 0x76a234dae870>: Failed to establish a new connection: [Errno 111] Connection refused'))
Error in VaultConfigSettingsSource: Vault error: HTTPConnectionPool(host='127.0.0.1', port=8200): Max retries exceeded with url: /v1/auth/token/lookup-self (Caused by NewConnectionError('<urllib3.connection.HTTPConnection object at 0x76a234db0c50>: Failed to establish a new connection: [Errno 111] Connection refused'))
Error in VaultConfigSettingsSource: Vault error: HTTPConnectionPool(host='127.0.0.1', port=8200): Max retries exceeded with url: /v1/auth/token/lookup-self (Caused by NewConnectionError('<urllib3.connection.HTTPConnection object at 0x76a234fb1c70>: Failed to establish a new connection: [Errno 111] Connection refused'))
Error in VaultConfigSettingsSource: Vault error: HTTPConnectionPool(host='127.0.0.1', port=8200): Max retries exceeded with url: /v1/auth/token/lookup-self (Caused by NewConnectionError('<urllib3.connection.HTTPConnection object at 0x76a234dacdd0>: Failed to establish a new connection: [Errno 111] Connection refused'))
Error in VaultConfigSettingsSource: Vault error: HTTPConnectionPool(host='127.0.0.1', port=8200): Max retries exceeded with url: /v1/auth/token/lookup-self (Caused by NewConnectionError('<urllib3.connection.HTTPConnection object at 0x76a234db3d40>: Failed to establish a new connection: [Errno 111] Connection refused'))
Error in VaultConfigSettingsSource: Vault error: HTTPConnectionPool(host='127.0.0.1', port=8200): Max retries exceeded with url: /v1/auth/token/lookup-self (Caused by NewConnectionError('<urllib3.connection.HTTPConnection object at 0x76a234fe75f0>: Failed to establish a new connection: [Errno 111] Connection refused'))
Error in VaultConfigSettingsSource: Vault error: HTTPConnectionPool(host='127.0.0.1', port=8200): Max retries exceeded with url: /v1/auth/token/lookup-self (Caused by NewConnectionError('<urllib3.connection.HTTPConnection object at 0x76a234dad040>: Failed to establish a new connection: [Errno 111] Connection refused'))
Error in VaultConfigSettingsSource: Vault error: HTTPConnectionPool(host='127.0.0.1', port=8200): Max retries exceeded with url: /v1/auth/token/lookup-self (Caused by NewConnectionError('<urllib3.connection.HTTPConnection object at 0x76a234e0db50>: Failed to establish a new connection: [Errno 111] Connection refused'))
[I 250210 22:07:48 command:168] Visit me at http://0.0.0.0:8888
[I 250210 22:07:49 command:176] Broker: redis://:**@localhost:6379/3
[I 250210 22:07:49 command:177] Registered tasks: 
    ['celery.accumulate',
     'celery.backend_cleanup',
     'celery.chain',
     'celery.chord',
     'celery.chord_unlock',
     'celery.chunks',
     'celery.group',
     'celery.map',
     'celery.starmap',
     'check_services_health',
     'process_order_workflow',
     'send_mail',
     'send_requests_for_create_order',
     'send_requests_for_get_result',
     'send_result_to_gd']
[I 250210 22:07:49 mixins:228] Connected to redis://:**@localhost:6379/3
[W 250210 22:07:50 inspector:44] Inspect method registered failed
[W 250210 22:07:50 inspector:44] Inspect method active failed
[W 250210 22:07:50 inspector:44] Inspect method conf failed
[W 250210 22:07:50 inspector:44] Inspect method active_queues failed
[W 250210 22:07:50 inspector:44] Inspect method revoked failed
[W 250210 22:07:50 inspector:44] Inspect method scheduled failed
[W 250210 22:07:50 inspector:44] Inspect method reserved failed
[W 250210 22:07:50 inspector:44] Inspect method stats failed
Error in VaultConfigSettingsSource: Vault error: HTTPConnectionPool(host='127.0.0.1', port=8200): Max retries exceeded with url: /v1/auth/token/lookup-self (Caused by NewConnectionError('<urllib3.connection.HTTPConnection object at 0x733145e01be0>: Failed to establish a new connection: [Errno 111] Connection refused'))
Error in VaultConfigSettingsSource: Vault error: HTTPConnectionPool(host='127.0.0.1', port=8200): Max retries exceeded with url: /v1/auth/token/lookup-self (Caused by NewConnectionError('<urllib3.connection.HTTPConnection object at 0x733145a42e10>: Failed to establish a new connection: [Errno 111] Connection refused'))
Error in VaultConfigSettingsSource: Vault error: HTTPConnectionPool(host='127.0.0.1', port=8200): Max retries exceeded with url: /v1/auth/token/lookup-self (Caused by NewConnectionError('<urllib3.connection.HTTPConnection object at 0x73314580d880>: Failed to establish a new connection: [Errno 111] Connection refused'))
Error in VaultConfigSettingsSource: Vault error: HTTPConnectionPool(host='127.0.0.1', port=8200): Max retries exceeded with url: /v1/auth/token/lookup-self (Caused by NewConnectionError('<urllib3.connection.HTTPConnection object at 0x733145812600>: Failed to establish a new connection: [Errno 111] Connection refused'))
Error in VaultConfigSettingsSource: Vault error: HTTPConnectionPool(host='127.0.0.1', port=8200): Max retries exceeded with url: /v1/auth/token/lookup-self (Caused by NewConnectionError('<urllib3.connection.HTTPConnection object at 0x733145a43a40>: Failed to establish a new connection: [Errno 111] Connection refused'))
Error in VaultConfigSettingsSource: Vault error: HTTPConnectionPool(host='127.0.0.1', port=8200): Max retries exceeded with url: /v1/auth/token/lookup-self (Caused by NewConnectionError('<urllib3.connection.HTTPConnection object at 0x73314580ea20>: Failed to establish a new connection: [Errno 111] Connection refused'))
Error in VaultConfigSettingsSource: Vault error: HTTPConnectionPool(host='127.0.0.1', port=8200): Max retries exceeded with url: /v1/auth/token/lookup-self (Caused by NewConnectionError('<urllib3.connection.HTTPConnection object at 0x733145810a40>: Failed to establish a new connection: [Errno 111] Connection refused'))
Error in VaultConfigSettingsSource: Vault error: HTTPConnectionPool(host='127.0.0.1', port=8200): Max retries exceeded with url: /v1/auth/token/lookup-self (Caused by NewConnectionError('<urllib3.connection.HTTPConnection object at 0x733145a13770>: Failed to establish a new connection: [Errno 111] Connection refused'))
Error in VaultConfigSettingsSource: Vault error: HTTPConnectionPool(host='127.0.0.1', port=8200): Max retries exceeded with url: /v1/auth/token/lookup-self (Caused by NewConnectionError('<urllib3.connection.HTTPConnection object at 0x73314580d100>: Failed to establish a new connection: [Errno 111] Connection refused'))
Error in VaultConfigSettingsSource: Vault error: HTTPConnectionPool(host='127.0.0.1', port=8200): Max retries exceeded with url: /v1/auth/token/lookup-self (Caused by NewConnectionError('<urllib3.connection.HTTPConnection object at 0x733145812360>: Failed to establish a new connection: [Errno 111] Connection refused'))
Error in VaultConfigSettingsSource: Vault error: HTTPConnectionPool(host='127.0.0.1', port=8200): Max retries exceeded with url: /v1/auth/token/lookup-self (Caused by NewConnectionError('<urllib3.connection.HTTPConnection object at 0x733145a42390>: Failed to establish a new connection: [Errno 111] Connection refused'))
Error in VaultConfigSettingsSource: Vault error: HTTPConnectionPool(host='127.0.0.1', port=8200): Max retries exceeded with url: /v1/auth/token/lookup-self (Caused by NewConnectionError('<urllib3.connection.HTTPConnection object at 0x733145885e20>: Failed to establish a new connection: [Errno 111] Connection refused'))
Error in VaultConfigSettingsSource: Vault error: HTTPConnectionPool(host='127.0.0.1', port=8200): Max retries exceeded with url: /v1/auth/token/lookup-self (Caused by NewConnectionError('<urllib3.connection.HTTPConnection object at 0x73314580edb0>: Failed to establish a new connection: [Errno 111] Connection refused'))
[I 250210 22:13:56 command:168] Visit me at http://0.0.0.0:8888
[I 250210 22:13:56 command:176] Broker: redis://:**@localhost:6379/3
[I 250210 22:13:56 command:177] Registered tasks: 
    ['celery.accumulate',
     'celery.backend_cleanup',
     'celery.chain',
     'celery.chord',
     'celery.chord_unlock',
     'celery.chunks',
     'celery.group',
     'celery.map',
     'celery.starmap',
     'check_services_health',
     'process_order_workflow',
     'send_mail',
     'send_requests_for_create_order',
     'send_requests_for_get_result',
     'send_result_to_gd']
[I 250210 22:13:56 mixins:228] Connected to redis://:**@localhost:6379/3
[W 250210 22:13:57 inspector:44] Inspect method reserved failed
[W 250210 22:13:57 inspector:44] Inspect method registered failed
[W 250210 22:13:57 inspector:44] Inspect method conf failed
[W 250210 22:13:57 inspector:44] Inspect method active_queues failed
[W 250210 22:13:57 inspector:44] Inspect method active failed
[W 250210 22:13:57 inspector:44] Inspect method revoked failed
[W 250210 22:13:57 inspector:44] Inspect method stats failed
[W 250210 22:13:57 inspector:44] Inspect method scheduled failed
Error in VaultConfigSettingsSource: Vault error: HTTPConnectionPool(host='127.0.0.1', port=8200): Max retries exceeded with url: /v1/auth/token/lookup-self (Caused by NewConnectionError('<urllib3.connection.HTTPConnection object at 0x7088ba334410>: Failed to establish a new connection: [Errno 111] Connection refused'))
Error in VaultConfigSettingsSource: Vault error: HTTPConnectionPool(host='127.0.0.1', port=8200): Max retries exceeded with url: /v1/auth/token/lookup-self (Caused by NewConnectionError('<urllib3.connection.HTTPConnection object at 0x7088ba336a80>: Failed to establish a new connection: [Errno 111] Connection refused'))
Error in VaultConfigSettingsSource: Vault error: HTTPConnectionPool(host='127.0.0.1', port=8200): Max retries exceeded with url: /v1/auth/token/lookup-self (Caused by NewConnectionError('<urllib3.connection.HTTPConnection object at 0x7088ba105880>: Failed to establish a new connection: [Errno 111] Connection refused'))
Error in VaultConfigSettingsSource: Vault error: HTTPConnectionPool(host='127.0.0.1', port=8200): Max retries exceeded with url: /v1/auth/token/lookup-self (Caused by NewConnectionError('<urllib3.connection.HTTPConnection object at 0x7088ba0fe480>: Failed to establish a new connection: [Errno 111] Connection refused'))
Error in VaultConfigSettingsSource: Vault error: HTTPConnectionPool(host='127.0.0.1', port=8200): Max retries exceeded with url: /v1/auth/token/lookup-self (Caused by NewConnectionError('<urllib3.connection.HTTPConnection object at 0x7088ba337710>: Failed to establish a new connection: [Errno 111] Connection refused'))
Error in VaultConfigSettingsSource: Vault error: HTTPConnectionPool(host='127.0.0.1', port=8200): Max retries exceeded with url: /v1/auth/token/lookup-self (Caused by NewConnectionError('<urllib3.connection.HTTPConnection object at 0x7088ba1065a0>: Failed to establish a new connection: [Errno 111] Connection refused'))
Error in VaultConfigSettingsSource: Vault error: HTTPConnectionPool(host='127.0.0.1', port=8200): Max retries exceeded with url: /v1/auth/token/lookup-self (Caused by NewConnectionError('<urllib3.connection.HTTPConnection object at 0x7088ba0ff8f0>: Failed to establish a new connection: [Errno 111] Connection refused'))
Error in VaultConfigSettingsSource: Vault error: HTTPConnectionPool(host='127.0.0.1', port=8200): Max retries exceeded with url: /v1/auth/token/lookup-self (Caused by NewConnectionError('<urllib3.connection.HTTPConnection object at 0x7088ba305a60>: Failed to establish a new connection: [Errno 111] Connection refused'))
Error in VaultConfigSettingsSource: Vault error: HTTPConnectionPool(host='127.0.0.1', port=8200): Max retries exceeded with url: /v1/auth/token/lookup-self (Caused by NewConnectionError('<urllib3.connection.HTTPConnection object at 0x7088ba105160>: Failed to establish a new connection: [Errno 111] Connection refused'))
Error in VaultConfigSettingsSource: Vault error: HTTPConnectionPool(host='127.0.0.1', port=8200): Max retries exceeded with url: /v1/auth/token/lookup-self (Caused by NewConnectionError('<urllib3.connection.HTTPConnection object at 0x7088ba0fffe0>: Failed to establish a new connection: [Errno 111] Connection refused'))
Error in VaultConfigSettingsSource: Vault error: HTTPConnectionPool(host='127.0.0.1', port=8200): Max retries exceeded with url: /v1/auth/token/lookup-self (Caused by NewConnectionError('<urllib3.connection.HTTPConnection object at 0x7088ba336c00>: Failed to establish a new connection: [Errno 111] Connection refused'))
Error in VaultConfigSettingsSource: Vault error: HTTPConnectionPool(host='127.0.0.1', port=8200): Max retries exceeded with url: /v1/auth/token/lookup-self (Caused by NewConnectionError('<urllib3.connection.HTTPConnection object at 0x7088ba106030>: Failed to establish a new connection: [Errno 111] Connection refused'))
Error in VaultConfigSettingsSource: Vault error: HTTPConnectionPool(host='127.0.0.1', port=8200): Max retries exceeded with url: /v1/auth/token/lookup-self (Caused by NewConnectionError('<urllib3.connection.HTTPConnection object at 0x7088ba175a60>: Failed to establish a new connection: [Errno 111] Connection refused'))
[I 250210 22:16:59 command:168] Visit me at http://0.0.0.0:8888
[I 250210 22:16:59 command:176] Broker: redis://:**@localhost:6379/3
[I 250210 22:16:59 command:177] Registered tasks: 
    ['celery.accumulate',
     'celery.backend_cleanup',
     'celery.chain',
     'celery.chord',
     'celery.chord_unlock',
     'celery.chunks',
     'celery.group',
     'celery.map',
     'celery.starmap',
     'check_services_health',
     'process_order_workflow',
     'send_mail',
     'send_requests_for_create_order',
     'send_requests_for_get_result',
     'send_result_to_gd']
[I 250210 22:16:59 mixins:228] Connected to redis://:**@localhost:6379/3
[W 250210 22:17:00 inspector:44] Inspect method scheduled failed
[W 250210 22:17:00 inspector:44] Inspect method stats failed
[W 250210 22:17:00 inspector:44] Inspect method registered failed
[W 250210 22:17:00 inspector:44] Inspect method reserved failed
[W 250210 22:17:00 inspector:44] Inspect method active_queues failed
[W 250210 22:17:00 inspector:44] Inspect method active failed
[W 250210 22:17:00 inspector:44] Inspect method revoked failed
[W 250210 22:17:00 inspector:44] Inspect method conf failed
Error in VaultConfigSettingsSource: Vault error: HTTPConnectionPool(host='127.0.0.1', port=8200): Max retries exceeded with url: /v1/auth/token/lookup-self (Caused by NewConnectionError('<urllib3.connection.HTTPConnection object at 0x7c0bf1ba69c0>: Failed to establish a new connection: [Errno 111] Connection refused'))
Error in VaultConfigSettingsSource: Vault error: HTTPConnectionPool(host='127.0.0.1', port=8200): Max retries exceeded with url: /v1/auth/token/lookup-self (Caused by NewConnectionError('<urllib3.connection.HTTPConnection object at 0x7c0bf1bd6cc0>: Failed to establish a new connection: [Errno 111] Connection refused'))
Error in VaultConfigSettingsSource: Vault error: HTTPConnectionPool(host='127.0.0.1', port=8200): Max retries exceeded with url: /v1/auth/token/lookup-self (Caused by NewConnectionError('<urllib3.connection.HTTPConnection object at 0x7c0bf19a58b0>: Failed to establish a new connection: [Errno 111] Connection refused'))
Error in VaultConfigSettingsSource: Vault error: HTTPConnectionPool(host='127.0.0.1', port=8200): Max retries exceeded with url: /v1/auth/token/lookup-self (Caused by NewConnectionError('<urllib3.connection.HTTPConnection object at 0x7c0bf199e4e0>: Failed to establish a new connection: [Errno 111] Connection refused'))
Error in VaultConfigSettingsSource: Vault error: HTTPConnectionPool(host='127.0.0.1', port=8200): Max retries exceeded with url: /v1/auth/token/lookup-self (Caused by NewConnectionError('<urllib3.connection.HTTPConnection object at 0x7c0bf1bd7d70>: Failed to establish a new connection: [Errno 111] Connection refused'))
Error in VaultConfigSettingsSource: Vault error: HTTPConnectionPool(host='127.0.0.1', port=8200): Max retries exceeded with url: /v1/auth/token/lookup-self (Caused by NewConnectionError('<urllib3.connection.HTTPConnection object at 0x7c0bf19a6900>: Failed to establish a new connection: [Errno 111] Connection refused'))
Error in VaultConfigSettingsSource: Vault error: HTTPConnectionPool(host='127.0.0.1', port=8200): Max retries exceeded with url: /v1/auth/token/lookup-self (Caused by NewConnectionError('<urllib3.connection.HTTPConnection object at 0x7c0bf199cc80>: Failed to establish a new connection: [Errno 111] Connection refused'))
Error in VaultConfigSettingsSource: Vault error: HTTPConnectionPool(host='127.0.0.1', port=8200): Max retries exceeded with url: /v1/auth/token/lookup-self (Caused by NewConnectionError('<urllib3.connection.HTTPConnection object at 0x7c0bf1ba6510>: Failed to establish a new connection: [Errno 111] Connection refused'))
Error in VaultConfigSettingsSource: Vault error: HTTPConnectionPool(host='127.0.0.1', port=8200): Max retries exceeded with url: /v1/auth/token/lookup-self (Caused by NewConnectionError('<urllib3.connection.HTTPConnection object at 0x7c0bf19a5130>: Failed to establish a new connection: [Errno 111] Connection refused'))
Error in VaultConfigSettingsSource: Vault error: HTTPConnectionPool(host='127.0.0.1', port=8200): Max retries exceeded with url: /v1/auth/token/lookup-self (Caused by NewConnectionError('<urllib3.connection.HTTPConnection object at 0x7c0bf199f530>: Failed to establish a new connection: [Errno 111] Connection refused'))
Error in VaultConfigSettingsSource: Vault error: HTTPConnectionPool(host='127.0.0.1', port=8200): Max retries exceeded with url: /v1/auth/token/lookup-self (Caused by NewConnectionError('<urllib3.connection.HTTPConnection object at 0x7c0bf1bd72f0>: Failed to establish a new connection: [Errno 111] Connection refused'))
Error in VaultConfigSettingsSource: Vault error: HTTPConnectionPool(host='127.0.0.1', port=8200): Max retries exceeded with url: /v1/auth/token/lookup-self (Caused by NewConnectionError('<urllib3.connection.HTTPConnection object at 0x7c0bf1a19b20>: Failed to establish a new connection: [Errno 111] Connection refused'))
Error in VaultConfigSettingsSource: Vault error: HTTPConnectionPool(host='127.0.0.1', port=8200): Max retries exceeded with url: /v1/auth/token/lookup-self (Caused by NewConnectionError('<urllib3.connection.HTTPConnection object at 0x7c0bf19a7470>: Failed to establish a new connection: [Errno 111] Connection refused'))
[I 250210 22:20:00 command:168] Visit me at http://0.0.0.0:8888
[I 250210 22:20:00 command:176] Broker: redis://:**@localhost:6379/3
[I 250210 22:20:00 command:177] Registered tasks: 
    ['celery.accumulate',
     'celery.backend_cleanup',
     'celery.chain',
     'celery.chord',
     'celery.chord_unlock',
     'celery.chunks',
     'celery.group',
     'celery.map',
     'celery.starmap',
     'check_services_health',
     'process_order_workflow',
     'send_mail',
     'send_requests_for_create_order',
     'send_requests_for_get_result',
     'send_result_to_gd']
[I 250210 22:20:01 mixins:228] Connected to redis://:**@localhost:6379/3
[W 250210 22:20:02 inspector:44] Inspect method conf failed
[W 250210 22:20:02 inspector:44] Inspect method registered failed
[W 250210 22:20:02 inspector:44] Inspect method active_queues failed
[W 250210 22:20:02 inspector:44] Inspect method revoked failed
[W 250210 22:20:02 inspector:44] Inspect method scheduled failed
[W 250210 22:20:02 inspector:44] Inspect method active failed
[W 250210 22:20:02 inspector:44] Inspect method reserved failed
[W 250210 22:20:02 inspector:44] Inspect method stats failed
Error in VaultConfigSettingsSource: Vault error: HTTPConnectionPool(host='127.0.0.1', port=8200): Max retries exceeded with url: /v1/auth/token/lookup-self (Caused by NewConnectionError('<urllib3.connection.HTTPConnection object at 0x78783e18c740>: Failed to establish a new connection: [Errno 111] Connection refused'))
Error in VaultConfigSettingsSource: Vault error: HTTPConnectionPool(host='127.0.0.1', port=8200): Max retries exceeded with url: /v1/auth/token/lookup-self (Caused by NewConnectionError('<urllib3.connection.HTTPConnection object at 0x78783e18ede0>: Failed to establish a new connection: [Errno 111] Connection refused'))
Error in VaultConfigSettingsSource: Vault error: HTTPConnectionPool(host='127.0.0.1', port=8200): Max retries exceeded with url: /v1/auth/token/lookup-self (Caused by NewConnectionError('<urllib3.connection.HTTPConnection object at 0x78783df59a00>: Failed to establish a new connection: [Errno 111] Connection refused'))
Error in VaultConfigSettingsSource: Vault error: HTTPConnectionPool(host='127.0.0.1', port=8200): Max retries exceeded with url: /v1/auth/token/lookup-self (Caused by NewConnectionError('<urllib3.connection.HTTPConnection object at 0x78783df56570>: Failed to establish a new connection: [Errno 111] Connection refused'))
Error in VaultConfigSettingsSource: Vault error: HTTPConnectionPool(host='127.0.0.1', port=8200): Max retries exceeded with url: /v1/auth/token/lookup-self (Caused by NewConnectionError('<urllib3.connection.HTTPConnection object at 0x78783df5ad80>: Failed to establish a new connection: [Errno 111] Connection refused'))
Error in VaultConfigSettingsSource: Vault error: HTTPConnectionPool(host='127.0.0.1', port=8200): Max retries exceeded with url: /v1/auth/token/lookup-self (Caused by NewConnectionError('<urllib3.connection.HTTPConnection object at 0x78783e18f6e0>: Failed to establish a new connection: [Errno 111] Connection refused'))
Error in VaultConfigSettingsSource: Vault error: HTTPConnectionPool(host='127.0.0.1', port=8200): Max retries exceeded with url: /v1/auth/token/lookup-self (Caused by NewConnectionError('<urllib3.connection.HTTPConnection object at 0x78783df54e00>: Failed to establish a new connection: [Errno 111] Connection refused'))
Error in VaultConfigSettingsSource: Vault error: HTTPConnectionPool(host='127.0.0.1', port=8200): Max retries exceeded with url: /v1/auth/token/lookup-self (Caused by NewConnectionError('<urllib3.connection.HTTPConnection object at 0x78783e162b40>: Failed to establish a new connection: [Errno 111] Connection refused'))
Error in VaultConfigSettingsSource: Vault error: HTTPConnectionPool(host='127.0.0.1', port=8200): Max retries exceeded with url: /v1/auth/token/lookup-self (Caused by NewConnectionError('<urllib3.connection.HTTPConnection object at 0x78783e18c6b0>: Failed to establish a new connection: [Errno 111] Connection refused'))
Error in VaultConfigSettingsSource: Vault error: HTTPConnectionPool(host='127.0.0.1', port=8200): Max retries exceeded with url: /v1/auth/token/lookup-self (Caused by NewConnectionError('<urllib3.connection.HTTPConnection object at 0x78783df56120>: Failed to establish a new connection: [Errno 111] Connection refused'))
Error in VaultConfigSettingsSource: Vault error: HTTPConnectionPool(host='127.0.0.1', port=8200): Max retries exceeded with url: /v1/auth/token/lookup-self (Caused by NewConnectionError('<urllib3.connection.HTTPConnection object at 0x78783df59f10>: Failed to establish a new connection: [Errno 111] Connection refused'))
Error in VaultConfigSettingsSource: Vault error: HTTPConnectionPool(host='127.0.0.1', port=8200): Max retries exceeded with url: /v1/auth/token/lookup-self (Caused by NewConnectionError('<urllib3.connection.HTTPConnection object at 0x78783dfc9bb0>: Failed to establish a new connection: [Errno 111] Connection refused'))
Error in VaultConfigSettingsSource: Vault error: HTTPConnectionPool(host='127.0.0.1', port=8200): Max retries exceeded with url: /v1/auth/token/lookup-self (Caused by NewConnectionError('<urllib3.connection.HTTPConnection object at 0x78783e18df70>: Failed to establish a new connection: [Errno 111] Connection refused'))
[I 250210 22:24:12 command:168] Visit me at http://0.0.0.0:8888
[I 250210 22:24:12 command:176] Broker: redis://:**@localhost:6379/3
[I 250210 22:24:12 command:177] Registered tasks: 
    ['celery.accumulate',
     'celery.backend_cleanup',
     'celery.chain',
     'celery.chord',
     'celery.chord_unlock',
     'celery.chunks',
     'celery.group',
     'celery.map',
     'celery.starmap',
     'check_services_health',
     'process_order_workflow',
     'send_mail',
     'send_requests_for_create_order',
     'send_requests_for_get_result',
     'send_result_to_gd']
[I 250210 22:24:12 mixins:228] Connected to redis://:**@localhost:6379/3
[W 250210 22:24:13 inspector:44] Inspect method revoked failed
[W 250210 22:24:13 inspector:44] Inspect method active_queues failed
[W 250210 22:24:13 inspector:44] Inspect method conf failed
[W 250210 22:24:13 inspector:44] Inspect method registered failed
[W 250210 22:24:13 inspector:44] Inspect method active failed
[W 250210 22:24:13 inspector:44] Inspect method reserved failed
[W 250210 22:24:13 inspector:44] Inspect method stats failed
[W 250210 22:24:13 inspector:44] Inspect method scheduled failed
Error in VaultConfigSettingsSource: Vault error: HTTPConnectionPool(host='127.0.0.1', port=8200): Max retries exceeded with url: /v1/auth/token/lookup-self (Caused by NewConnectionError('<urllib3.connection.HTTPConnection object at 0x76dc1dfaf8f0>: Failed to establish a new connection: [Errno 111] Connection refused'))
Error in VaultConfigSettingsSource: Vault error: HTTPConnectionPool(host='127.0.0.1', port=8200): Max retries exceeded with url: /v1/auth/token/lookup-self (Caused by NewConnectionError('<urllib3.connection.HTTPConnection object at 0x76dc1dbe2990>: Failed to establish a new connection: [Errno 111] Connection refused'))
Error in VaultConfigSettingsSource: Vault error: HTTPConnectionPool(host='127.0.0.1', port=8200): Max retries exceeded with url: /v1/auth/token/lookup-self (Caused by NewConnectionError('<urllib3.connection.HTTPConnection object at 0x76dc1d9ada30>: Failed to establish a new connection: [Errno 111] Connection refused'))
Error in VaultConfigSettingsSource: Vault error: HTTPConnectionPool(host='127.0.0.1', port=8200): Max retries exceeded with url: /v1/auth/token/lookup-self (Caused by NewConnectionError('<urllib3.connection.HTTPConnection object at 0x76dc1d98e450>: Failed to establish a new connection: [Errno 111] Connection refused'))
Error in VaultConfigSettingsSource: Vault error: HTTPConnectionPool(host='127.0.0.1', port=8200): Max retries exceeded with url: /v1/auth/token/lookup-self (Caused by NewConnectionError('<urllib3.connection.HTTPConnection object at 0x76dc1dbe33e0>: Failed to establish a new connection: [Errno 111] Connection refused'))
Error in VaultConfigSettingsSource: Vault error: HTTPConnectionPool(host='127.0.0.1', port=8200): Max retries exceeded with url: /v1/auth/token/lookup-self (Caused by NewConnectionError('<urllib3.connection.HTTPConnection object at 0x76dc1d9ad040>: Failed to establish a new connection: [Errno 111] Connection refused'))
Error in VaultConfigSettingsSource: Vault error: HTTPConnectionPool(host='127.0.0.1', port=8200): Max retries exceeded with url: /v1/auth/token/lookup-self (Caused by NewConnectionError('<urllib3.connection.HTTPConnection object at 0x76dc1d98cc20>: Failed to establish a new connection: [Errno 111] Connection refused'))
Error in VaultConfigSettingsSource: Vault error: HTTPConnectionPool(host='127.0.0.1', port=8200): Max retries exceeded with url: /v1/auth/token/lookup-self (Caused by NewConnectionError('<urllib3.connection.HTTPConnection object at 0x76dc1dbb3770>: Failed to establish a new connection: [Errno 111] Connection refused'))
Error in VaultConfigSettingsSource: Vault error: HTTPConnectionPool(host='127.0.0.1', port=8200): Max retries exceeded with url: /v1/auth/token/lookup-self (Caused by NewConnectionError('<urllib3.connection.HTTPConnection object at 0x76dc1d9ad8e0>: Failed to establish a new connection: [Errno 111] Connection refused'))
Error in VaultConfigSettingsSource: Vault error: HTTPConnectionPool(host='127.0.0.1', port=8200): Max retries exceeded with url: /v1/auth/token/lookup-self (Caused by NewConnectionError('<urllib3.connection.HTTPConnection object at 0x76dc1d98f8c0>: Failed to establish a new connection: [Errno 111] Connection refused'))
Error in VaultConfigSettingsSource: Vault error: HTTPConnectionPool(host='127.0.0.1', port=8200): Max retries exceeded with url: /v1/auth/token/lookup-self (Caused by NewConnectionError('<urllib3.connection.HTTPConnection object at 0x76dc1dbe0740>: Failed to establish a new connection: [Errno 111] Connection refused'))
Error in VaultConfigSettingsSource: Vault error: HTTPConnectionPool(host='127.0.0.1', port=8200): Max retries exceeded with url: /v1/auth/token/lookup-self (Caused by NewConnectionError('<urllib3.connection.HTTPConnection object at 0x76dc1d9afad0>: Failed to establish a new connection: [Errno 111] Connection refused'))
Error in VaultConfigSettingsSource: Vault error: HTTPConnectionPool(host='127.0.0.1', port=8200): Max retries exceeded with url: /v1/auth/token/lookup-self (Caused by NewConnectionError('<urllib3.connection.HTTPConnection object at 0x76dc1da21580>: Failed to establish a new connection: [Errno 111] Connection refused'))
[I 250210 22:26:58 command:168] Visit me at http://0.0.0.0:8888
[I 250210 22:26:58 command:176] Broker: redis://:**@localhost:6379/3
[I 250210 22:26:58 command:177] Registered tasks: 
    ['celery.accumulate',
     'celery.backend_cleanup',
     'celery.chain',
     'celery.chord',
     'celery.chord_unlock',
     'celery.chunks',
     'celery.group',
     'celery.map',
     'celery.starmap',
     'check_services_health',
     'process_order_workflow',
     'send_mail',
     'send_requests_for_create_order',
     'send_requests_for_get_result',
     'send_result_to_gd']
[I 250210 22:26:58 mixins:228] Connected to redis://:**@localhost:6379/3
[W 250210 22:26:59 inspector:44] Inspect method reserved failed
[W 250210 22:26:59 inspector:44] Inspect method scheduled failed
[W 250210 22:26:59 inspector:44] Inspect method active_queues failed
[W 250210 22:26:59 inspector:44] Inspect method registered failed
[W 250210 22:26:59 inspector:44] Inspect method revoked failed
[W 250210 22:26:59 inspector:44] Inspect method active failed
[W 250210 22:26:59 inspector:44] Inspect method conf failed
[W 250210 22:26:59 inspector:44] Inspect method stats failed
Error in VaultConfigSettingsSource: Vault error: HTTPConnectionPool(host='127.0.0.1', port=8200): Max retries exceeded with url: /v1/auth/token/lookup-self (Caused by NewConnectionError('<urllib3.connection.HTTPConnection object at 0x7eb63bd344d0>: Failed to establish a new connection: [Errno 111] Connection refused'))
Error in VaultConfigSettingsSource: Vault error: HTTPConnectionPool(host='127.0.0.1', port=8200): Max retries exceeded with url: /v1/auth/token/lookup-self (Caused by NewConnectionError('<urllib3.connection.HTTPConnection object at 0x7eb63bd36ab0>: Failed to establish a new connection: [Errno 111] Connection refused'))
Error in VaultConfigSettingsSource: Vault error: HTTPConnectionPool(host='127.0.0.1', port=8200): Max retries exceeded with url: /v1/auth/token/lookup-self (Caused by NewConnectionError('<urllib3.connection.HTTPConnection object at 0x7eb63bb218e0>: Failed to establish a new connection: [Errno 111] Connection refused'))
Error in VaultConfigSettingsSource: Vault error: HTTPConnectionPool(host='127.0.0.1', port=8200): Max retries exceeded with url: /v1/auth/token/lookup-self (Caused by NewConnectionError('<urllib3.connection.HTTPConnection object at 0x7eb63bb2e480>: Failed to establish a new connection: [Errno 111] Connection refused'))
Error in VaultConfigSettingsSource: Vault error: HTTPConnectionPool(host='127.0.0.1', port=8200): Max retries exceeded with url: /v1/auth/token/lookup-self (Caused by NewConnectionError('<urllib3.connection.HTTPConnection object at 0x7eb63bd37dd0>: Failed to establish a new connection: [Errno 111] Connection refused'))
Error in VaultConfigSettingsSource: Vault error: HTTPConnectionPool(host='127.0.0.1', port=8200): Max retries exceeded with url: /v1/auth/token/lookup-self (Caused by NewConnectionError('<urllib3.connection.HTTPConnection object at 0x7eb63bb22ab0>: Failed to establish a new connection: [Errno 111] Connection refused'))
Error in VaultConfigSettingsSource: Vault error: HTTPConnectionPool(host='127.0.0.1', port=8200): Max retries exceeded with url: /v1/auth/token/lookup-self (Caused by NewConnectionError('<urllib3.connection.HTTPConnection object at 0x7eb63bb2cbf0>: Failed to establish a new connection: [Errno 111] Connection refused'))
Error in VaultConfigSettingsSource: Vault error: HTTPConnectionPool(host='127.0.0.1', port=8200): Max retries exceeded with url: /v1/auth/token/lookup-self (Caused by NewConnectionError('<urllib3.connection.HTTPConnection object at 0x7eb63bd03830>: Failed to establish a new connection: [Errno 111] Connection refused'))
Error in VaultConfigSettingsSource: Vault error: HTTPConnectionPool(host='127.0.0.1', port=8200): Max retries exceeded with url: /v1/auth/token/lookup-self (Caused by NewConnectionError('<urllib3.connection.HTTPConnection object at 0x7eb63bb21580>: Failed to establish a new connection: [Errno 111] Connection refused'))
Error in VaultConfigSettingsSource: Vault error: HTTPConnectionPool(host='127.0.0.1', port=8200): Max retries exceeded with url: /v1/auth/token/lookup-self (Caused by NewConnectionError('<urllib3.connection.HTTPConnection object at 0x7eb63bb2c260>: Failed to establish a new connection: [Errno 111] Connection refused'))
Error in VaultConfigSettingsSource: Vault error: HTTPConnectionPool(host='127.0.0.1', port=8200): Max retries exceeded with url: /v1/auth/token/lookup-self (Caused by NewConnectionError('<urllib3.connection.HTTPConnection object at 0x7eb63bd34350>: Failed to establish a new connection: [Errno 111] Connection refused'))
Error in VaultConfigSettingsSource: Vault error: HTTPConnectionPool(host='127.0.0.1', port=8200): Max retries exceeded with url: /v1/auth/token/lookup-self (Caused by NewConnectionError('<urllib3.connection.HTTPConnection object at 0x7eb63bb99c40>: Failed to establish a new connection: [Errno 111] Connection refused'))
Error in VaultConfigSettingsSource: Vault error: HTTPConnectionPool(host='127.0.0.1', port=8200): Max retries exceeded with url: /v1/auth/token/lookup-self (Caused by NewConnectionError('<urllib3.connection.HTTPConnection object at 0x7eb63bb20350>: Failed to establish a new connection: [Errno 111] Connection refused'))
